Workbook

Sheet 00.사용안내
B2: L6(Task 단위) 프로세스 취합양식 v14
B3: 과제 #4 · 마켓센싱 리포트 AI 전환 | 에스원 AX/PI센터 PI그룹 · 260814
B5: ★ 핵심 | C5: L5 프로세스 1개는 L6 Task 3개 이상으로 쪼개집니다. L5 이름을 단어만 바꿔 L6 칸에 옮겨 적으면(1:1) AI 설계에 쓸 수 없습니다. [02.L6 세분화] 맨 오른쪽 [검증] 열이 1:1 행과 미입력 칸을 자동으로 표시합니다.
B7: ★ TO-BE 3단 구분 | C7: TO-BE 를 세 칸으로 나눠 적습니다. 섞어 쓰면 취합 때 집계가 안 됩니다. ① 변화 유형 — 어떻게 바뀌나 : 유지 · 변경 · 신설 · 삭제 ② 적용 수단 — 무엇으로 : AI · N-ERP · 시스템(AI 외) · 없음 ③ 수행 주체 — 결국 누가 : 사람 · 시스템 · AI · AI+사람 예) 사람이 엑셀로 집계하던 것을 AI 가 자동 집계 → ① 변경 ② AI ③ AI 예) 사람 판단을 AI 초안 + 사람 확정으로 → ① 변경 ② AI ③ AI+사람 예) N-ERP 표준기능 개선으로 자동 처리 → ① 변경 ② N-ERP ③ 시스템 예) 룰엔진·RPA 로 자동 처리 → ① 변경 ② 시스템(AI 외) ③ 시스템 예) 그대로 사람이 한다 → ① 유지 ② 없음 ③ 사람 ※ "자동화" 는 ① 값이 아닙니다. 「변경 + AI」 또는 「변경 + 시스템」 으로 적습니다. ※ ③ 수행 주체는 AS-IS · TO-BE 가 같은 목록입니다. 두 칸을 비교하면 무엇이 넘어가는지 보입니다.
B9: ★ 비워 둔 칸 | C9: PI그룹이 판단할 수 없어 비워 둔 칸입니다. 현업만 채울 수 있습니다. · 수행조직 (AS-IS · TO-BE) — 실제 수행 부서·팀 · 소요시간 · 인원 수 · 빈도 단위 · 빈도 횟수 · 연 대상 건수 (분홍 머리글) · 기타 KPI — 공수·시간 외에 관리하는 지표가 있을 때만 · 작성자 · 작성일 숫자 칸에는 숫자만 들어갑니다. 모르면 비우고 [추가 필요내용] 에 무엇을 모르는지 적어 주세요.
B11: ★ 회신 전에 [검증] 4칸만 보세요 | C11: 맨 오른쪽 [검증] 4칸이 자동으로 검사해 줍니다. 경고일 뿐 입력을 막지는 않습니다. ① 몇 개로 쪼갰나 같은 L5 에 몇 줄을 썼는지 ② 충분히 쪼갰나 ⚠ 1개뿐 / △ 2개뿐 / △ 하는 일이 N가지뿐 / ○ 좋음 ★ 줄 수만 늘리고 내용이 비슷하면 「하는 일이 N가지뿐」 으로 잡힙니다 하는 일 = 찾기 · 만들기 · 확인하기 · 넘기기. 전부 「만들기」 면 자료를 어디서 가져오는지, 완성본을 어디에 올리는지를 안 적은 것입니다 ③ 빈칸 있나 시간 계산에 필요한 칸이 몇 개 비었는지 (신설 줄은 현재 칸을, 삭제 줄은 개선 후 칸을 세지 않습니다) ④ 고칠 점 있나 같은 말 반복 · 덜 쪼갠 것 · 앞뒤 안 맞는 것을 짚어 줍니다 문제가 있는 줄은 왼쪽이 붉게(⚠) 또는 주황(△)으로 칠해집니다. 각 머리글에 마우스를 올리면 무엇을 검사하는지 전부 나옵니다.
B13: ★ [기준] 칸은 비워도 됩니다 | C13: 판단 기준이 있을 때만 적습니다. 없으면 그냥 비워 두세요. 적는 것 — 무엇을 보고 「된다 / 안 된다」 를 가르나 「도급액 30억 이상이면 RM파트, 30억 미만이면 엔지니어링팀장」 「하도급 비율 50% 초과면 위반」 「전월 대비 변동 폭이 크고 사업 영향도가 높은 것」 적지 않는 것 — 언제 · 누구에게 · 어떤 형식으로 하는지 「대상 : 전 프로젝트」 「주기 : 월 1회」 「수신 : 임원」 「형식 : 3줄 요약」 기준을 글로 쓸 수 있으면 그대로 자동화됩니다. 쓸 수 없으면 사람 감각으로 하는 일이라는 뜻이고, 그 일은 사람이 계속 맡게 됩니다.
B15: 시트 구성 | C15: 00.사용안내 이 시트 01.과제 개요 과제 배경 · 목표 · 대상 프로세스 (읽기용) 02.L6 세분화 ★ 입력 시트. 여기에만 씁니다 03.전체 프로세스 목록 본 과제가 속한 L1 기능의 전 프로세스 (참조 · 누락 점검) 04.코드표 드롭다운 원본 · 환산 계수
B17: 쓰는 순서 | C17: ① [01.과제 개요] 로 과제의 배경·목표·대상 프로세스를 확인합니다. ② [02.L6 세분화] 상단 노란 밴드의 작성 규칙을 읽습니다. (스크롤해도 계속 보입니다) ③ 연노랑 초안 행을 실제 업무에 맞게 고치고, 빠진 Task 를 아래에 이어서 적습니다. ④ 비어 있는 칸을 채웁니다. 열 머리글에 마우스를 올리면 작성 요령이 뜹니다. ⑤ [03.전체 프로세스 목록] 에서 「⚠ 과제 범위 · L6 미작성」 행이 남아 있는지 확인합니다. ⑥ [검증] 3개 열에 ⚠ 가 없는지 확인한 뒤, 파일명 뒤에 본인 이름을 붙여 회신합니다.
B19: 화면 조작 | C19: · 틀 고정 — [업무 내용] 열까지 고정. 오른쪽으로 스크롤해도 남습니다. · 머리글 색 — 청색 = AS-IS · 주황 = 변화 유형 · 녹색 = TO-BE · 분홍 = 숫자 입력 · 회색 = 자동 계산 · 열 그룹 — 상단 1 / 2 버튼과 ± 로 AS-IS · TO-BE 블록을 각각 접을 수 있습니다 · 자동 필터 — 머리글 행 필터로 수행 주체 · 검증 결과 등을 걸러 볼 수 있습니다
B21: Task 분리 기준 | C21: L6 세분화 가이드라인 v1 기준. 다음 중 하나라도 바뀌면 별도 행으로 나눕니다. · 수행자(담당자·부서)가 바뀔 때 · 시스템 · 도구가 바뀔 때 · 의사결정(승인 · 확정 · 판단)이 발생할 때 ★ AI 적용 난이도 판단에 중요 · Input 데이터의 종류 · 출처가 바뀔 때 · 산출물(Output)이 바뀔 때 ※ 통상 1~30분 내 완료 단위. 클릭 1회 같은 5초 이하 동작까지는 내려가지 않습니다.
B23: 환산 기준 | C23: · 1 FTE = 2,000 H / 년 · 연간 공수(H) = 소요시간(분) × 인원 수 × 연환산 ÷ 60 · 빈도 환산계수 : 일 250 · 주 52 · 월 12 · 건별/비정기 = 각 행의 [연 대상 건수] 값 · 위 값은 [04.코드표] 에서 바꿀 수 있고, 바꾸면 효과 산출 열 전체가 갱신됩니다.

Sheet 01.과제 개요
B2: 과제 개요
B3: 출처 : PI Portal [E2E 과제현황] · N-ERP To-Be 프로세스 체계도 | 값은 원본 그대로입니다.
B5: 항목 | C5: 내용
B6: 1. 과제 식별
B7: 과제 번호 | C7: PI Portal E2E 과제현황 #4 (종전 #1)
B8: 과제명 | C8: 마켓센싱 리포트 AI 전환
B9: 부문 | C9: 시큐리티
B10: 주관 (제출) | C10: 임원 : 김현국 상무 조직장 : 운영팀장
B11: 대상 프로세스 | C11: 연결된 최말단 프로세스 10건 · 1.1.2.5.1 마케팅 > Market Intelligence > MI 정보수집 > 수집 대상 자료 리서치 > 기 보유 MI정보리스트 우선 검색 · 1.1.2.8.1 마케팅 > Market Intelligence > MI 정보수집 > 보고서 등록 > MI 시스템에 조사 보고서 등록 · 1.1.2.10.1 마케팅 > Market Intelligence > MI 정보수집 > 자료/데이터 요청 > 자료/데이터 요청 · 1.1.3.4.1 마케팅 > Market Intelligence > MI 정보분석 및 시사점 도출 > 기술 환경 분석 > 기술 환경 분석 · 1.1.3.5.1 마케팅 > Market Intelligence > MI 정보분석 및 시사점 도출 > 시사점 도출 > 환경분석 시사점도출 · 1.1.3.12.1 마케팅 > Market Intelligence > MI 정보분석 및 시사점 도출 > 경쟁사 상품 비교 분석 > 경쟁사 상품 비교 분석 · 1.1.3.19.1 마케팅 > Market Intelligence > MI 정보분석 및 시사점 도출 > 주요 시사점 도출 > 고객분석 시사점 도출 · 1.1.3.20.1 마케팅 > Market Intelligence > MI 정보분석 및 시사점 도출 > 조사 보고서 작성 > 일간 MI뉴스 작성 · 1.1.3.20.2 마케팅 > Market Intelligence > MI 정보분석 및 시사점 도출 > 조사 보고서 작성 > 시장환경분석서작성 · 1.1.3.20.3 마케팅 > Market Intelligence > MI 정보분석 및 시사점 도출 > 조사 보고서 작성 > 월간 MI리포트 작성
B12: 2. 배경 · 현상
B13: Weak Point 유형 | C13: 병목
B14: 현상 | C14: 수집·정리·정형화·분석을 사람이 수작업 반복하고, 주제 선정과 인사이트 도출이 암묵지·특정인에 의존해 품질 편차가 발생한다
B15: 3. 개선 방향
B16: 개선 내용 | C16: 정형·반복 업무(수집·정리·시각화)는 자동화로 대체하고, 주제 선정·인사이트 도출은 4개 관점(상품/서비스·영업/채널·기술/인프라·마케팅) 다관점 AI 에이전트와 암묵지 자산화로 고도화한다 — 최종 판단은 사람
B17: Tool | C17: AI
B18: 자동화 수준 | C18: A (원본 코드 그대로)
B19: 필요 데이터 | C19: 공공·정책 자료, 미디어·뉴스, 연구·전문보고서, 국내외 기술전, 트렌드 뉴스레터
B20: 데이터 보유 시스템 | C20: 정책브리핑 · 국가데이터처 · 주요 언론사 · 한국은행/KDI/산업연구원 · 광고사 뉴스레터
B21: 4. 기대효과
B22: 효과 구분 | C22: 효율 제고
B23: KPI | C23: · 지표 : 업무 공수 · AS-IS : 0.5H/일 · 1MM · TO-BE : 0.05H/일 · 0.1MM
B24: L6 실측 절감 | C24: [02.L6 세분화] 의 효과 산출 열에 자동 계산됩니다. 인원 수 1 이상인 행(사람 공수)만 집계합니다. · 1 FTE = 2,000 H / 년 현재는 소요시간·인원 값이 비어 있어 0 으로 표시됩니다.
B25: 5. 안내
B26: 초안 범위 | C26: [02.L6 세분화] 의 연노랑 행 22건은 임원 제출자료에 근거가 있는 프로세스 5개를 PI그룹이 L6 로 쪼갠 제안입니다. 확정본이 아닙니다. 업무 내용 · 수행 주체 · Input · 산출물 · TO-BE 설명은 PI그룹 작성입니다. 실제 업무와 다르면 고치고, 빠진 Task 는 이어서 적어 주세요. 나머지 행은 매핑된 프로세스를 한 줄씩 깔아 둔 것입니다 — 해당 업무를 하신다면 그 줄도 L6 로 쪼개 주시고, 우리 업무가 아니면 [추가 필요내용] 에 그렇게 적어 주세요.
B27: 비워 둔 칸 | C27: 수행조직 · 소요시간 · 인원 수 · 빈도 단위 · 빈도 횟수 · 연 대상 건수 · 기타 KPI · 작성자 → PI그룹이 판단할 수 없는 값입니다. 추정치를 넣지 않았습니다.
B28: 확인 필요 | C28: ① [02.L6 세분화] 의 빈칸 전부 ② L6 분해(안) 이 실제 업무 순서·범위와 맞는지 — 빠진 Task · 불필요한 Task · 순서 ③ 연결된 프로세스가 본 과제 범위와 맞는지 (틀리면 알려 주세요 — 매핑을 고칩니다) ④ 담당 작성자 · 회신 기한

Sheet 02.L6 세분화
B2: L6(Task 단위) 프로세스 세분화 — 과제 #4 · 마켓센싱 리포트 AI 전환
B3: ★ L5 1개 → L6 3개 이상. L5 이름을 단어만 바꿔 옮겨 적으면(1:1) AI 설계에 쓸 수 없습니다. 맨 오른쪽 [검증] 열이 1:1 행과 미입력 칸을 자동으로 잡아냅니다. 쪼개는 법 ▶ ① 무엇이 이 업무를 시작시키나 → ② 시작 전 무엇을 찾아보나(조회·수집) → ③ 찾은 것으로 무엇을 만드나(작성·생성) → ④ 맞는지 누가 확인하나(검증·판단·승인) → ⑤ 결과는 어디로 가나(등록·발송·보고) TO-BE 3단 ▶ ① 변화 유형 = 어떻게 바뀌나 (유지 · 변경 · 신설 · 삭제) ② 적용 수단 = 무엇으로 (AI · N-ERP · 시스템(AI 외) · 없음) ③ 수행 주체 = 결국 누가 (사람 · 시스템 · AI · AI+사람) 산출물 ▶ AS-IS · TO-BE 각각 적습니다. 앞 행의 [산출물] 이 뒷 행의 [필요 데이터] 로 이어지면 순서가 맞습니다. 문장 ▶ 쓰지 말 것 : 관리한다 · 처리한다 · 수행한다 · 진행한다 쓸 것 : 조회 · 입력 · 산출 · 판정 · 검토 · 승인 · 발송 · 등록 1행 = 1 Task 주어·괄호 없이 "~한다" 로 종결 분홍 머리글 칸 ▶ 숫자만 넣습니다. 모르면 비워 두고 [추가 필요내용] 에 적어 주세요. ● 필수 · ◐ 조건부(빈도 단위에 따라 하나만) 회색 열은 자동 계산이라 입력하지 않습니다. 빈도는 AS-IS 만 씁니다. [검증] 4칸 ▶ 몇 개로 쪼갰나 · 충분히 쪼갰나 · 빈칸 있나 · 고칠 점 있나. 문제가 있는 행은 왼쪽이 붉게(⚠) 또는 주황(△)으로 칠해집니다. 경고일 뿐 입력을 막지는 않습니다. 머리글에 마우스를 올리면 무엇을 검사하는지 다 나옵니다. [기준] ▶ 판단 기준이 있을 때만 적습니다. 「대상 : 전 프로젝트」 「주기 : 월 1회」 같은 건 기준이 아니라서 안 적습니다.
B4: 식별 · 프로세스 연결 (사전 채움) | L4: 업무 정의 | N4: AS-IS 현재 업무 | X4: 변화 | Y4: TO-BE 개선 후 | AH4: 효과 산출 (자동계산) | AL4: 판단 · 보완 | AP4: 검증 (자동계산) | AT4: 취합
B5: No | C5: ● L5 / 프로세스 ID | D5: 과제ID | E5: ● 부문 | F5: ● L1 | G5: ● L2 | H5: ● L3 | I5: ● L4 | J5: ● L5 | K5: L6 ID (자동) | L5: ● 업무 내용 (L6) "~를 ~한다" | M5: 기준 (있을 때만) | N5: ● ③ 수행 주체 | O5: 수행조직 | P5: ● 소요시간 (분/건) | Q5: ● 인원 수 | R5: ● 빈도 단위 | S5: ◐ 빈도 횟수 | T5: ◐ 연 대상 건수 | U5: ● 필요 데이터 (Input) | V5: ● 산출물 (Output) | W5: ◐ 데이터 위치 (시스템) | X5: ● ① 변화 유형 | Y5: ● ② 적용 수단 | Z5: ● TO-BE 프로세스 설명 | AA5: ● ③ 수행 주체 | AB5: 수행조직 | AC5: ● 소요시간 (분/건) | AD5: ● 인원 수 | AE5: 필요 데이터 (Input) | AF5: ● 산출물 (Output) | AG5: 데이터 위치 (시스템) | AH5: 연간 AS-IS 공수(H) | AI5: 연간 TO-BE 공수(H) | AJ5: 절감 (H/년) | AK5: 절감 FTE | AL5: 의사결정 복잡도 | AM5: 불편한 점 (Weak Point) | AN5: 기타 KPI (공수 · 시간 외) | AO5: 추가 필요내용 (비고) | AP5: [검증] 이 L5의 Task 수 | AQ5: [검증] 쪼개기 상태 | AR5: [검증] 빈칸 | AS5: [검증] 고칠 점 | AT5: 작성자 | AU5: 작성일
B6: 1 | C6: 1.1.2.5.1 | D6: #4 | E6: 시큐리티 | F6: 마케팅 | G6: Market Intelligence | H6: MI 정보수집 | I6: 수집 대상 자료 리서치 | J6: 기 보유 MI정보리스트 우선 검색 | K6: =IF($L6="","",$C6&"-"&TEXT(COUNTIFS($C$6:$C6,$C6),"00")) -> 1.1.2.5.1-01 | L6: 공공·정책, 미디어, 연구보고서 등 기본 채널에서 대상 자료를 수집한다 | N6: 사람 | P6: 15 | Q6: 1 | R6: 일 | S6: 1 | T6: 0 | U6: 공공·정책 자료, 미디어·뉴스, 연구·전문보고서, 기술전 정보, 트렌드 뉴스레터 | V6: 수집 원자료 | W6: 외부 | X6: 변경 | Y6: AI | Z6: 5개 기본축 채널을 크롤링으로 자동 수집해 분석가의 수동 소싱을 대체한다 | AA6: AI | AE6: 공공·정책 자료, 미디어·뉴스, 연구·전문보고서, 기술전 정보, 트렌드 뉴스레터 | AF6: 수집 원자료 | AG6: AI Agent DB | AH6: =IF(OR($Q6="",$Q6=0,$P6=""),0,ROUND($P6*$Q6*IFERROR(IF($R6="건별/비정기",$T6,VLOOKUP($R6,'04.코드표'!$K$5:$L$8,2,FALSE)*$S6),0)/60,1)) -> 62.5 | AI6: =IF(OR($AD6="",$AD6=0,$AC6=""),0,ROUND($AC6*$AD6*IFERROR(IF($R6="건별/비정기",$T6,VLOOKUP($R6,'04.코드표'!$K$5:$L$8,2,FALSE)*$S6),0)/60,1)) -> 0 | AJ6: =IF($L6="","",$AH6-$AI6) -> 62.5 | AK6: =IF($L6="","",ROUND($AJ6/'04.코드표'!$L$11,2)) -> 0.03 | AL6: 하 | AM6: 5개 축을 사람이 매번 수동으로 돌며 소싱해 반복작업에 시간이 과다 소모된다 | AP6: =IF($L6="","",COUNTIFS($C$6:$C$62,$C6)) -> 4 | AQ6: =IF($L6="","",IF($AP6=1,"⚠ 1개뿐 — 더 쪼개세요",IF($AP6=2,"△ 2개뿐 — 빠진 단계 확인",IF($AZ6<=2,"△ 하는 일이 "&$AZ6&"가지뿐 — 빠진 단계 확인","○ 좋음 (하는 일 "&$AZ6&"가지)")))) -> ○ 좋음 (하는 일 3가지) | AR6: =IF($L6="","",IF($BA6=0,"○ 다 채웠음","⚠ "&$BA6&"칸 비었음")) -> ⚠ 2칸 비었음 | AS6: =IF($L6="","",IF($BB6="","○ 문제 없음","⚠ "&LEFT($BB6,LEN($BB6)-3))) -> ○ 문제 없음 | AV6: =IF($L6="","",TRIM(RIGHT(SUBSTITUTE($AW6," ",REPT(" ",120)),120))) -> 수집한다 | AW6: =SUBSTITUTE($L6,CHAR(10)," ") -> 공공·정책, 미디어, 연구보고서 등 기본 채널에서 대상 자료를 수집한다 | AX6: =SUBSTITUTE($J6,CHAR(10)," ") -> 기 보유 MI정보리스트 우선 검색 | AY6: =IF($L6="","",IF(SUMPRODUCT(--ISNUMBER(SEARCH({"조회","수집","추출","검색","파악","취합","조달","접수","연계","연동","선별","확보","입수","조사","식별","검출","감지","스크랩","필터링"},$AV6)))>0,"조회",IF(SUMPRODUCT(--ISNUMBER(SEARCH({"검토","검증","판정","판별","확인","승인","선정","대조","점검","분류","확정","평가","판단","심사","검수","비교","결정","구분","진단","판독","협의"},$AV6)))>0,"검증",IF(SUMPRODUCT(--ISNUMBER(SEARCH({"등록","발송","배포","제출","보고","이관","업로드","비치","공유","통보","알림","축적","저장","안내","제시","전달","회신","게시","기록","전파","제공","공지","요청","지시","배정","회부"},$AV6)))>0,"등록",IF(SUMPRODUCT(--ISNUMBER(SEARCH({"작성","생성","산출","제작","입력","정리","집계","분석","정형화","도출","보정","구성","정렬","반영","수립","설계","보완","요약","번역","정의","산정","갱신","수정","편성","설정","누적","가공","변환","시각화","편집","통합","부여","정제","기입","조정","제거","표시","채번"},$AV6)))>0,"작성","기타"))))) -> 조회 | AZ6: =IF($L6="","",(COUNTIFS($C$6:$C$62,$C6,$AY$6:$AY$62,"조회")>0)+(COUNTIFS($C$6:$C$62,$C6,$AY$6:$AY$62,"작성")>0)+(COUNTIFS($C$6:$C$62,$C6,$AY$6:$AY$62,"검증")>0)+(COUNTIFS($C$6:$C$62,$C6,$AY$6:$AY$62,"등록")>0)) -> 3 | BA6: =IF($L6="",0,IF($X6="신설",0,COUNTBLANK($N6)+COUNTBLANK($P6)+COUNTBLANK($Q6)+COUNTBLANK($R6)+IF($R6="건별/비정기",COUNTBLANK($T6),IF($R6="",0,COUNTBLANK($S6))))+IF($X6="삭제",0,COUNTBLANK($AC6)+COUNTBLANK($AD6))) -> 2 | BB6: =IF($L6="","",IF(AND($AX6<>"",ISNUMBER(SEARCH($AX6,$AW6))),"L5 이름을 그대로 씀 · ","")&IF(AND($L6<>"",$L6=$Z6),"개선 후 설명이 똑같음 · ","")&IF(COUNTIFS($C$6:$C$62,$C6,$L$6:$L$62,$L6)>1,"같은 내용이 또 있음 · ","")&IF(AND($U6<>"",$U6=$V6),"필요 자료와 산출물이 같음 · ","")&IF(AND($C6=$C5,$V5<>"",$U6<>"",ISERROR(SEARCH(SUBSTITUTE($V5,CHAR(10)," "),SUBSTITUTE($U6,CHAR(10)," "))),ISERROR(SEARCH(SUBSTITUTE($U6,CHAR(10)," "),SUBSTITUTE($V5,CHAR(10)," ")))),"앞 산출물과 이어지지 않음 · ","")&IF(SUMPRODUCT(--ISNUMBER(SEARCH({"관리한다","처리한다","수행한다","진행한다"},$AW6)))>0,"뭉뚱그린 동사 · ","")&IF(ISNUMBER(SEARCH("하고 ",$AW6)),"한 줄에 동작 2개 · ","")&IF(RIGHT($L6,2)<>"한다","~한다 로 안 끝남 · ","")&IF(AND($P6<>"",N($P6)>60),"1건 60분 넘음 — 더 쪼개세요 · ","")&IF(AND($AA6="AI",$AD6<>"",N($AD6)>0),"AI 혼자 하는데 사람 인원 있음 · ","")&IF(AND($AA6="AI+사람",$AD6<>"",N($AD6)=0),"사람이 확인한다는데 인원 0 · ","")&IF(AND($X6="유지",$Y6="AI"),"그대로 두는데 AI 를 쓴다고 함 · ","")&IF(AND($X6="신설",COUNT($P6,$Q6)>0),"새로 생기는 일인데 현재 공수가 있음 · ","")&IF(AND($X6="삭제",COUNT($AC6,$AD6)>0),"없애는 일인데 개선 후 공수가 있음 · ","")&IF(AND($X6<>"신설",N($AH6)>0,N($AI6)>N($AH6)),"개선 후가 지금보다 더 오래 걸림 · ","")) | BC6: =IFERROR(IF($L6="",0,1/$AP6),0) -> 0.25
B7: 2 | C7: 1.1.2.5.1 | D7: #4 | E7: 시큐리티 | F7: 마케팅 | G7: Market Intelligence | H7: MI 정보수집 | I7: 수집 대상 자료 리서치 | J7: 기 보유 MI정보리스트 우선 검색 | K7: =IF($L7="","",$C7&"-"&TEXT(COUNTIFS($C$6:$C7,$C7),"00")) -> 1.1.2.5.1-02 | L7: 기 보유 MI정보리스트와 대조하여 중복 자료를 제거한다 | N7: 사람 | P7: 5 | Q7: 1 | R7: 주 | S7: 1 | T7: 0 | U7: 수집 원자료, 기 보유 MI정보리스트 | V7: 중복 제거된 자료 목록 | W7: 확인 필요 | X7: 변경 | Y7: AI | Z7: 기 보유 리스트와의 대조가 자동 수행되어 중복 자료가 수집 단계에서 걸러진다 | AA7: AI | AE7: 수집 원자료, 기 보유 MI정보리스트 | AF7: 중복 제거된 자료 목록 | AG7: AI Agent DB | AH7: =IF(OR($Q7="",$Q7=0,$P7=""),0,ROUND($P7*$Q7*IFERROR(IF($R7="건별/비정기",$T7,VLOOKUP($R7,'04.코드표'!$K$5:$L$8,2,FALSE)*$S7),0)/60,1)) -> 4.3 | AI7: =IF(OR($AD7="",$AD7=0,$AC7=""),0,ROUND($AC7*$AD7*IFERROR(IF($R7="건별/비정기",$T7,VLOOKUP($R7,'04.코드표'!$K$5:$L$8,2,FALSE)*$S7),0)/60,1)) -> 0 | AJ7: =IF($L7="","",$AH7-$AI7) -> 4.3 | AK7: =IF($L7="","",ROUND($AJ7/'04.코드표'!$L$11,2)) -> 0 | AL7: 하 | AM7: 이미 보유한 자료인지 사람이 일일이 검색해 확인해야 한다 | AP7: =IF($L7="","",COUNTIFS($C$6:$C$62,$C7)) -> 4 | AQ7: =IF($L7="","",IF($AP7=1,"⚠ 1개뿐 — 더 쪼개세요",IF($AP7=2,"△ 2개뿐 — 빠진 단계 확인",IF($AZ7<=2,"△ 하는 일이 "&$AZ7&"가지뿐 — 빠진 단계 확인","○ 좋음 (하는 일 "&$AZ7&"가지)")))) -> ○ 좋음 (하는 일 3가지) | AR7: =IF($L7="","",IF($BA7=0,"○ 다 채웠음","⚠ "&$BA7&"칸 비었음")) -> ⚠ 2칸 비었음 | AS7: =IF($L7="","",IF($BB7="","○ 문제 없음","⚠ "&LEFT($BB7,LEN($BB7)-3))) -> ○ 문제 없음 | AV7: =IF($L7="","",TRIM(RIGHT(SUBSTITUTE($AW7," ",REPT(" ",120)),120))) -> 제거한다 | AW7: =SUBSTITUTE($L7,CHAR(10)," ") -> 기 보유 MI정보리스트와 대조하여 중복 자료를 제거한다 | AX7: =SUBSTITUTE($J7,CHAR(10)," ") -> 기 보유 MI정보리스트 우선 검색 | AY7: =IF($L7="","",IF(SUMPRODUCT(--ISNUMBER(SEARCH({"조회","수집","추출","검색","파악","취합","조달","접수","연계","연동","선별","확보","입수","조사","식별","검출","감지","스크랩","필터링"},$AV7)))>0,"조회",IF(SUMPRODUCT(--ISNUMBER(SEARCH({"검토","검증","판정","판별","확인","승인","선정","대조","점검","분류","확정","평가","판단","심사","검수","비교","결정","구분","진단","판독","협의"},$AV7)))>0,"검증",IF(SUMPRODUCT(--ISNUMBER(SEARCH({"등록","발송","배포","제출","보고","이관","업로드","비치","공유","통보","알림","축적","저장","안내","제시","전달","회신","게시","기록","전파","제공","공지","요청","지시","배정","회부"},$AV7)))>0,"등록",IF(SUMPRODUCT(--ISNUMBER(SEARCH({"작성","생성","산출","제작","입력","정리","집계","분석","정형화","도출","보정","구성","정렬","반영","수립","설계","보완","요약","번역","정의","산정","갱신","수정","편성","설정","누적","가공","변환","시각화","편집","통합","부여","정제","기입","조정","제거","표시","채번"},$AV7)))>0,"작성","기타"))))) -> 작성 | AZ7: =IF($L7="","",(COUNTIFS($C$6:$C$62,$C7,$AY$6:$AY$62,"조회")>0)+(COUNTIFS($C$6:$C$62,$C7,$AY$6:$AY$62,"작성")>0)+(COUNTIFS($C$6:$C$62,$C7,$AY$6:$AY$62,"검증")>0)+(COUNTIFS($C$6:$C$62,$C7,$AY$6:$AY$62,"등록")>0)) -> 3 | BA7: =IF($L7="",0,IF($X7="신설",0,COUNTBLANK($N7)+COUNTBLANK($P7)+COUNTBLANK($Q7)+COUNTBLANK($R7)+IF($R7="건별/비정기",COUNTBLANK($T7),IF($R7="",0,COUNTBLANK($S7))))+IF($X7="삭제",0,COUNTBLANK($AC7)+COUNTBLANK($AD7))) -> 2 | BB7: =IF($L7="","",IF(AND($AX7<>"",ISNUMBER(SEARCH($AX7,$AW7))),"L5 이름을 그대로 씀 · ","")&IF(AND($L7<>"",$L7=$Z7),"개선 후 설명이 똑같음 · ","")&IF(COUNTIFS($C$6:$C$62,$C7,$L$6:$L$62,$L7)>1,"같은 내용이 또 있음 · ","")&IF(AND($U7<>"",$U7=$V7),"필요 자료와 산출물이 같음 · ","")&IF(AND($C7=$C5,$V5<>"",$U7<>"",ISERROR(SEARCH(SUBSTITUTE($V5,CHAR(10)," "),SUBSTITUTE($U7,CHAR(10)," "))),ISERROR(SEARCH(SUBSTITUTE($U7,CHAR(10)," "),SUBSTITUTE($V5,CHAR(10)," ")))),"앞 산출물과 이어지지 않음 · ","")&IF(SUMPRODUCT(--ISNUMBER(SEARCH({"관리한다","처리한다","수행한다","진행한다"},$AW7)))>0,"뭉뚱그린 동사 · ","")&IF(ISNUMBER(SEARCH("하고 ",$AW7)),"한 줄에 동작 2개 · ","")&IF(RIGHT($L7,2)<>"한다","~한다 로 안 끝남 · ","")&IF(AND($P7<>"",N($P7)>60),"1건 60분 넘음 — 더 쪼개세요 · ","")&IF(AND($AA7="AI",$AD7<>"",N($AD7)>0),"AI 혼자 하는데 사람 인원 있음 · ","")&IF(AND($AA7="AI+사람",$AD7<>"",N($AD7)=0),"사람이 확인한다는데 인원 0 · ","")&IF(AND($X7="유지",$Y7="AI"),"그대로 두는데 AI 를 쓴다고 함 · ","")&IF(AND($X7="신설",COUNT($P7,$Q7)>0),"새로 생기는 일인데 현재 공수가 있음 · ","")&IF(AND($X7="삭제",COUNT($AC7,$AD7)>0),"없애는 일인데 개선 후 공수가 있음 · ","")&IF(AND($X7<>"신설",N($AH7)>0,N($AI7)>N($AH7)),"개선 후가 지금보다 더 오래 걸림 · ","")) | BC7: =IFERROR(IF($L7="",0,1/$AP7),0) -> 0.25
B8: 3 | C8: 1.1.2.5.1 | D8: #4 | E8: 시큐리티 | F8: 마케팅 | G8: Market Intelligence | H8: MI 정보수집 | I8: 수집 대상 자료 리서치 | J8: 기 보유 MI정보리스트 우선 검색 | K8: =IF($L8="","",$C8&"-"&TEXT(COUNTIFS($C$6:$C8,$C8),"00")) -> 1.1.2.5.1-03 | L8: 정의된 선별 기준에 따라 수집 자료를 1차 선별한다 | M8: 자료가 정의된 조사 범위와 선별 기준에 부합하는지 여부 | N8: 사람 | P8: 15 | Q8: 1 | R8: 주 | S8: 1 | T8: 0 | U8: 중복 제거된 자료 목록, 범위·선별 기준 | V8: 1차 선별 자료 | W8: offline(개인PC) | X8: 변경 | Y8: AI | Z8: AI가 사전 정의된 선별 기준으로 1차 선별을 수행하고 분석가는 경계 사례만 확인한다 | AA8: AI+사람 | AE8: 중복 제거된 자료 목록, 범위·선별 기준 | AF8: 1차 선별 자료 | AG8: AI Agent DB | AH8: =IF(OR($Q8="",$Q8=0,$P8=""),0,ROUND($P8*$Q8*IFERROR(IF($R8="건별/비정기",$T8,VLOOKUP($R8,'04.코드표'!$K$5:$L$8,2,FALSE)*$S8),0)/60,1)) -> 13 | AI8: =IF(OR($AD8="",$AD8=0,$AC8=""),0,ROUND($AC8*$AD8*IFERROR(IF($R8="건별/비정기",$T8,VLOOKUP($R8,'04.코드표'!$K$5:$L$8,2,FALSE)*$S8),0)/60,1)) -> 0 | AJ8: =IF($L8="","",$AH8-$AI8) -> 13 | AK8: =IF($L8="","",ROUND($AJ8/'04.코드표'!$L$11,2)) -> 0.01 | AL8: 상 | AM8: 무엇을 왜 뽑는지가 암묵지로 남아 특정인에 의존하고 품질 편차가 발생한다 | AP8: =IF($L8="","",COUNTIFS($C$6:$C$62,$C8)) -> 4 | AQ8: =IF($L8="","",IF($AP8=1,"⚠ 1개뿐 — 더 쪼개세요",IF($AP8=2,"△ 2개뿐 — 빠진 단계 확인",IF($AZ8<=2,"△ 하는 일이 "&$AZ8&"가지뿐 — 빠진 단계 확인","○ 좋음 (하는 일 "&$AZ8&"가지)")))) -> ○ 좋음 (하는 일 3가지) | AR8: =IF($L8="","",IF($BA8=0,"○ 다 채웠음","⚠ "&$BA8&"칸 비었음")) -> ⚠ 2칸 비었음 | AS8: =IF($L8="","",IF($BB8="","○ 문제 없음","⚠ "&LEFT($BB8,LEN($BB8)-3))) -> ○ 문제 없음 | AV8: =IF($L8="","",TRIM(RIGHT(SUBSTITUTE($AW8," ",REPT(" ",120)),120))) -> 선별한다 | AW8: =SUBSTITUTE($L8,CHAR(10)," ") -> 정의된 선별 기준에 따라 수집 자료를 1차 선별한다 | AX8: =SUBSTITUTE($J8,CHAR(10)," ") -> 기 보유 MI정보리스트 우선 검색 | AY8: =IF($L8="","",IF(SUMPRODUCT(--ISNUMBER(SEARCH({"조회","수집","추출","검색","파악","취합","조달","접수","연계","연동","선별","확보","입수","조사","식별","검출","감지","스크랩","필터링"},$AV8)))>0,"조회",IF(SUMPRODUCT(--ISNUMBER(SEARCH({"검토","검증","판정","판별","확인","승인","선정","대조","점검","분류","확정","평가","판단","심사","검수","비교","결정","구분","진단","판독","협의"},$AV8)))>0,"검증",IF(SUMPRODUCT(--ISNUMBER(SEARCH({"등록","발송","배포","제출","보고","이관","업로드","비치","공유","통보","알림","축적","저장","안내","제시","전달","회신","게시","기록","전파","제공","공지","요청","지시","배정","회부"},$AV8)))>0,"등록",IF(SUMPRODUCT(--ISNUMBER(SEARCH({"작성","생성","산출","제작","입력","정리","집계","분석","정형화","도출","보정","구성","정렬","반영","수립","설계","보완","요약","번역","정의","산정","갱신","수정","편성","설정","누적","가공","변환","시각화","편집","통합","부여","정제","기입","조정","제거","표시","채번"},$AV8)))>0,"작성","기타"))))) -> 조회 | AZ8: =IF($L8="","",(COUNTIFS($C$6:$C$62,$C8,$AY$6:$AY$62,"조회")>0)+(COUNTIFS($C$6:$C$62,$C8,$AY$6:$AY$62,"작성")>0)+(COUNTIFS($C$6:$C$62,$C8,$AY$6:$AY$62,"검증")>0)+(COUNTIFS($C$6:$C$62,$C8,$AY$6:$AY$62,"등록")>0)) -> 3 | BA8: =IF($L8="",0,IF($X8="신설",0,COUNTBLANK($N8)+COUNTBLANK($P8)+COUNTBLANK($Q8)+COUNTBLANK($R8)+IF($R8="건별/비정기",COUNTBLANK($T8),IF($R8="",0,COUNTBLANK($S8))))+IF($X8="삭제",0,COUNTBLANK($AC8)+COUNTBLANK($AD8))) -> 2 | BB8: =IF($L8="","",IF(AND($AX8<>"",ISNUMBER(SEARCH($AX8,$AW8))),"L5 이름을 그대로 씀 · ","")&IF(AND($L8<>"",$L8=$Z8),"개선 후 설명이 똑같음 · ","")&IF(COUNTIFS($C$6:$C$62,$C8,$L$6:$L$62,$L8)>1,"같은 내용이 또 있음 · ","")&IF(AND($U8<>"",$U8=$V8),"필요 자료와 산출물이 같음 · ","")&IF(AND($C8=$C5,$V5<>"",$U8<>"",ISERROR(SEARCH(SUBSTITUTE($V5,CHAR(10)," "),SUBSTITUTE($U8,CHAR(10)," "))),ISERROR(SEARCH(SUBSTITUTE($U8,CHAR(10)," "),SUBSTITUTE($V5,CHAR(10)," ")))),"앞 산출물과 이어지지 않음 · ","")&IF(SUMPRODUCT(--ISNUMBER(SEARCH({"관리한다","처리한다","수행한다","진행한다"},$AW8)))>0,"뭉뚱그린 동사 · ","")&IF(ISNUMBER(SEARCH("하고 ",$AW8)),"한 줄에 동작 2개 · ","")&IF(RIGHT($L8,2)<>"한다","~한다 로 안 끝남 · ","")&IF(AND($P8<>"",N($P8)>60),"1건 60분 넘음 — 더 쪼개세요 · ","")&IF(AND($AA8="AI",$AD8<>"",N($AD8)>0),"AI 혼자 하는데 사람 인원 있음 · ","")&IF(AND($AA8="AI+사람",$AD8<>"",N($AD8)=0),"사람이 확인한다는데 인원 0 · ","")&IF(AND($X8="유지",$Y8="AI"),"그대로 두는데 AI 를 쓴다고 함 · ","")&IF(AND($X8="신설",COUNT($P8,$Q8)>0),"새로 생기는 일인데 현재 공수가 있음 · ","")&IF(AND($X8="삭제",COUNT($AC8,$AD8)>0),"없애는 일인데 개선 후 공수가 있음 · ","")&IF(AND($X8<>"신설",N($AH8)>0,N($AI8)>N($AH8)),"개선 후가 지금보다 더 오래 걸림 · ","")) | BC8: =IFERROR(IF($L8="",0,1/$AP8),0) -> 0.25
B9: 4 | C9: 1.1.2.5.1 | D9: #4 | E9: 시큐리티 | F9: 마케팅 | G9: Market Intelligence | H9: MI 정보수집 | I9: 수집 대상 자료 리서치 | J9: 기 보유 MI정보리스트 우선 검색 | K9: =IF($L9="","",$C9&"-"&TEXT(COUNTIFS($C$6:$C9,$C9),"00")) -> 1.1.2.5.1-04 | L9: 선별 결과와 채택·기각 사유를 지식 계층에 기록한다 | N9: 사람 | P9: 5 | Q9: 1 | R9: 주 | S9: 1 | T9: 0 | U9: 1차 선별 자료, 채택·기각 판단 근거 | V9: 채택/기각 기록 | W9: offline(개인PC) | X9: 신설 | Y9: AI | Z9: 채택과 기각의 근거를 표준 양식으로 구조화해 기록하고 이후 학습 데이터로 활용한다 | AA9: AI+사람 | AE9: 1차 선별 자료, 채택·기각 판단 근거 | AF9: 채택/기각 기록 | AG9: AI Agent DB | AH9: =IF(OR($Q9="",$Q9=0,$P9=""),0,ROUND($P9*$Q9*IFERROR(IF($R9="건별/비정기",$T9,VLOOKUP($R9,'04.코드표'!$K$5:$L$8,2,FALSE)*$S9),0)/60,1)) -> 4.3 | AI9: =IF(OR($AD9="",$AD9=0,$AC9=""),0,ROUND($AC9*$AD9*IFERROR(IF($R9="건별/비정기",$T9,VLOOKUP($R9,'04.코드표'!$K$5:$L$8,2,FALSE)*$S9),0)/60,1)) -> 0 | AJ9: =IF($L9="","",$AH9-$AI9) -> 4.3 | AK9: =IF($L9="","",ROUND($AJ9/'04.코드표'!$L$11,2)) -> 0 | AL9: 중 | AM9: 왜 뽑고 왜 버렸는지가 기록되지 않아 판단 근거가 조직에 남지 않는다 | AP9: =IF($L9="","",COUNTIFS($C$6:$C$62,$C9)) -> 4 | AQ9: =IF($L9="","",IF($AP9=1,"⚠ 1개뿐 — 더 쪼개세요",IF($AP9=2,"△ 2개뿐 — 빠진 단계 확인",IF($AZ9<=2,"△ 하는 일이 "&$AZ9&"가지뿐 — 빠진 단계 확인","○ 좋음 (하는 일 "&$AZ9&"가지)")))) -> ○ 좋음 (하는 일 3가지) | AR9: =IF($L9="","",IF($BA9=0,"○ 다 채웠음","⚠ "&$BA9&"칸 비었음")) -> ⚠ 2칸 비었음 | AS9: =IF($L9="","",IF($BB9="","○ 문제 없음","⚠ "&LEFT($BB9,LEN($BB9)-3))) -> ⚠ 새로 생기는 일인데 현재 공수가 있음 | AV9: =IF($L9="","",TRIM(RIGHT(SUBSTITUTE($AW9," ",REPT(" ",120)),120))) -> 기록한다 | AW9: =SUBSTITUTE($L9,CHAR(10)," ") -> 선별 결과와 채택·기각 사유를 지식 계층에 기록한다 | AX9: =SUBSTITUTE($J9,CHAR(10)," ") -> 기 보유 MI정보리스트 우선 검색 | AY9: =IF($L9="","",IF(SUMPRODUCT(--ISNUMBER(SEARCH({"조회","수집","추출","검색","파악","취합","조달","접수","연계","연동","선별","확보","입수","조사","식별","검출","감지","스크랩","필터링"},$AV9)))>0,"조회",IF(SUMPRODUCT(--ISNUMBER(SEARCH({"검토","검증","판정","판별","확인","승인","선정","대조","점검","분류","확정","평가","판단","심사","검수","비교","결정","구분","진단","판독","협의"},$AV9)))>0,"검증",IF(SUMPRODUCT(--ISNUMBER(SEARCH({"등록","발송","배포","제출","보고","이관","업로드","비치","공유","통보","알림","축적","저장","안내","제시","전달","회신","게시","기록","전파","제공","공지","요청","지시","배정","회부"},$AV9)))>0,"등록",IF(SUMPRODUCT(--ISNUMBER(SEARCH({"작성","생성","산출","제작","입력","정리","집계","분석","정형화","도출","보정","구성","정렬","반영","수립","설계","보완","요약","번역","정의","산정","갱신","수정","편성","설정","누적","가공","변환","시각화","편집","통합","부여","정제","기입","조정","제거","표시","채번"},$AV9)))>0,"작성","기타"))))) -> 등록 | AZ9: =IF($L9="","",(COUNTIFS($C$6:$C$62,$C9,$AY$6:$AY$62,"조회")>0)+(COUNTIFS($C$6:$C$62,$C9,$AY$6:$AY$62,"작성")>0)+(COUNTIFS($C$6:$C$62,$C9,$AY$6:$AY$62,"검증")>0)+(COUNTIFS($C$6:$C$62,$C9,$AY$6:$AY$62,"등록")>0)) -> 3 | BA9: =IF($L9="",0,IF($X9="신설",0,COUNTBLANK($N9)+COUNTBLANK($P9)+COUNTBLANK($Q9)+COUNTBLANK($R9)+IF($R9="건별/비정기",COUNTBLANK($T9),IF($R9="",0,COUNTBLANK($S9))))+IF($X9="삭제",0,COUNTBLANK($AC9)+COUNTBLANK($AD9))) -> 2 | BB9: =IF($L9="","",IF(AND($AX9<>"",ISNUMBER(SEARCH($AX9,$AW9))),"L5 이름을 그대로 씀 · ","")&IF(AND($L9<>"",$L9=$Z9),"개선 후 설명이 똑같음 · ","")&IF(COUNTIFS($C$6:$C$62,$C9,$L$6:$L$62,$L9)>1,"같은 내용이 또 있음 · ","")&IF(AND($U9<>"",$U9=$V9),"필요 자료와 산출물이 같음 · ","")&IF(AND($C9=$C5,$V5<>"",$U9<>"",ISERROR(SEARCH(SUBSTITUTE($V5,CHAR(10)," "),SUBSTITUTE($U9,CHAR(10)," "))),ISERROR(SEARCH(SUBSTITUTE($U9,CHAR(10)," "),SUBSTITUTE($V5,CHAR(10)," ")))),"앞 산출물과 이어지지 않음 · ","")&IF(SUMPRODUCT(--ISNUMBER(SEARCH({"관리한다","처리한다","수행한다","진행한다"},$AW9)))>0,"뭉뚱그린 동사 · ","")&IF(ISNUMBER(SEARCH("하고 ",$AW9)),"한 줄에 동작 2개 · ","")&IF(RIGHT($L9,2)<>"한다","~한다 로 안 끝남 · ","")&IF(AND($P9<>"",N($P9)>60),"1건 60분 넘음 — 더 쪼개세요 · ","")&IF(AND($AA9="AI",$AD9<>"",N($AD9)>0),"AI 혼자 하는데 사람 인원 있음 · ","")&IF(AND($AA9="AI+사람",$AD9<>"",N($AD9)=0),"사람이 확인한다는데 인원 0 · ","")&IF(AND($X9="유지",$Y9="AI"),"그대로 두는데 AI 를 쓴다고 함 · ","")&IF(AND($X9="신설",COUNT($P9,$Q9)>0),"새로 생기는 일인데 현재 공수가 있음 · ","")&IF(AND($X9="삭제",COUNT($AC9,$AD9)>0),"없애는 일인데 개선 후 공수가 있음 · ","")&IF(AND($X9<>"신설",N($AH9)>0,N($AI9)>N($AH9)),"개선 후가 지금보다 더 오래 걸림 · ","")) -> 새로 생기는 일인데 현재 공수가 있음 · | BC9: =IFERROR(IF($L9="",0,1/$AP9),0) -> 0.25
B10: 5 | C10: 1.1.2.8.1 | D10: #4 | E10: 시큐리티 | F10: 마케팅 | G10: Market Intelligence | H10: MI 정보수집 | I10: 보고서 등록 | J10: MI 시스템에 조사 보고서 등록 | K10: =IF($L10="","",$C10&"-"&TEXT(COUNTIFS($C$6:$C10,$C10),"00")) | AH10: =IF(OR($Q10="",$Q10=0,$P10=""),0,ROUND($P10*$Q10*IFERROR(IF($R10="건별/비정기",$T10,VLOOKUP($R10,'04.코드표'!$K$5:$L$8,2,FALSE)*$S10),0)/60,1)) -> 0 | AI10: =IF(OR($AD10="",$AD10=0,$AC10=""),0,ROUND($AC10*$AD10*IFERROR(IF($R10="건별/비정기",$T10,VLOOKUP($R10,'04.코드표'!$K$5:$L$8,2,FALSE)*$S10),0)/60,1)) -> 0 | AJ10: =IF($L10="","",$AH10-$AI10) | AK10: =IF($L10="","",ROUND($AJ10/'04.코드표'!$L$11,2)) | AP10: =IF($L10="","",COUNTIFS($C$6:$C$62,$C10)) | AQ10: =IF($L10="","",IF($AP10=1,"⚠ 1개뿐 — 더 쪼개세요",IF($AP10=2,"△ 2개뿐 — 빠진 단계 확인",IF($AZ10<=2,"△ 하는 일이 "&$AZ10&"가지뿐 — 빠진 단계 확인","○ 좋음 (하는 일 "&$AZ10&"가지)")))) | AR10: =IF($L10="","",IF($BA10=0,"○ 다 채웠음","⚠ "&$BA10&"칸 비었음")) | AS10: =IF($L10="","",IF($BB10="","○ 문제 없음","⚠ "&LEFT($BB10,LEN($BB10)-3))) | AV10: =IF($L10="","",TRIM(RIGHT(SUBSTITUTE($AW10," ",REPT(" ",120)),120))) | AW10: =SUBSTITUTE($L10,CHAR(10)," ") | AX10: =SUBSTITUTE($J10,CHAR(10)," ") -> MI 시스템에 조사 보고서 등록 | AY10: =IF($L10="","",IF(SUMPRODUCT(--ISNUMBER(SEARCH({"조회","수집","추출","검색","파악","취합","조달","접수","연계","연동","선별","확보","입수","조사","식별","검출","감지","스크랩","필터링"},$AV10)))>0,"조회",IF(SUMPRODUCT(--ISNUMBER(SEARCH({"검토","검증","판정","판별","확인","승인","선정","대조","점검","분류","확정","평가","판단","심사","검수","비교","결정","구분","진단","판독","협의"},$AV10)))>0,"검증",IF(SUMPRODUCT(--ISNUMBER(SEARCH({"등록","발송","배포","제출","보고","이관","업로드","비치","공유","통보","알림","축적","저장","안내","제시","전달","회신","게시","기록","전파","제공","공지","요청","지시","배정","회부"},$AV10)))>0,"등록",IF(SUMPRODUCT(--ISNUMBER(SEARCH({"작성","생성","산출","제작","입력","정리","집계","분석","정형화","도출","보정","구성","정렬","반영","수립","설계","보완","요약","번역","정의","산정","갱신","수정","편성","설정","누적","가공","변환","시각화","편집","통합","부여","정제","기입","조정","제거","표시","채번"},$AV10)))>0,"작성","기타"))))) | AZ10: =IF($L10="","",(COUNTIFS($C$6:$C$62,$C10,$AY$6:$AY$62,"조회")>0)+(COUNTIFS($C$6:$C$62,$C10,$AY$6:$AY$62,"작성")>0)+(COUNTIFS($C$6:$C$62,$C10,$AY$6:$AY$62,"검증")>0)+(COUNTIFS($C$6:$C$62,$C10,$AY$6:$AY$62,"등록")>0)) | BA10: =IF($L10="",0,IF($X10="신설",0,COUNTBLANK($N10)+COUNTBLANK($P10)+COUNTBLANK($Q10)+COUNTBLANK($R10)+IF($R10="건별/비정기",COUNTBLANK($T10),IF($R10="",0,COUNTBLANK($S10))))+IF($X10="삭제",0,COUNTBLANK($AC10)+COUNTBLANK($AD10))) -> 0 | BB10: =IF($L10="","",IF(AND($AX10<>"",ISNUMBER(SEARCH($AX10,$AW10))),"L5 이름을 그대로 씀 · ","")&IF(AND($L10<>"",$L10=$Z10),"개선 후 설명이 똑같음 · ","")&IF(COUNTIFS($C$6:$C$62,$C10,$L$6:$L$62,$L10)>1,"같은 내용이 또 있음 · ","")&IF(AND($U10<>"",$U10=$V10),"필요 자료와 산출물이 같음 · ","")&IF(AND($C10=$C5,$V5<>"",$U10<>"",ISERROR(SEARCH(SUBSTITUTE($V5,CHAR(10)," "),SUBSTITUTE($U10,CHAR(10)," "))),ISERROR(SEARCH(SUBSTITUTE($U10,CHAR(10)," "),SUBSTITUTE($V5,CHAR(10)," ")))),"앞 산출물과 이어지지 않음 · ","")&IF(SUMPRODUCT(--ISNUMBER(SEARCH({"관리한다","처리한다","수행한다","진행한다"},$AW10)))>0,"뭉뚱그린 동사 · ","")&IF(ISNUMBER(SEARCH("하고 ",$AW10)),"한 줄에 동작 2개 · ","")&IF(RIGHT($L10,2)<>"한다","~한다 로 안 끝남 · ","")&IF(AND($P10<>"",N($P10)>60),"1건 60분 넘음 — 더 쪼개세요 · ","")&IF(AND($AA10="AI",$AD10<>"",N($AD10)>0),"AI 혼자 하는데 사람 인원 있음 · ","")&IF(AND($AA10="AI+사람",$AD10<>"",N($AD10)=0),"사람이 확인한다는데 인원 0 · ","")&IF(AND($X10="유지",$Y10="AI"),"그대로 두는데 AI 를 쓴다고 함 · ","")&IF(AND($X10="신설",COUNT($P10,$Q10)>0),"새로 생기는 일인데 현재 공수가 있음 · ","")&IF(AND($X10="삭제",COUNT($AC10,$AD10)>0),"없애는 일인데 개선 후 공수가 있음 · ","")&IF(AND($X10<>"신설",N($AH10)>0,N($AI10)>N($AH10)),"개선 후가 지금보다 더 오래 걸림 · ","")) | BC10: =IFERROR(IF($L10="",0,1/$AP10),0) -> 0
B11: 6 | C11: 1.1.2.10.1 | D11: #4 | E11: 시큐리티 | F11: 마케팅 | G11: Market Intelligence | H11: MI 정보수집 | I11: 자료/데이터 요청 | J11: 자료/데이터 요청 | K11: =IF($L11="","",$C11&"-"&TEXT(COUNTIFS($C$6:$C11,$C11),"00")) | AH11: =IF(OR($Q11="",$Q11=0,$P11=""),0,ROUND($P11*$Q11*IFERROR(IF($R11="건별/비정기",$T11,VLOOKUP($R11,'04.코드표'!$K$5:$L$8,2,FALSE)*$S11),0)/60,1)) -> 0 | AI11: =IF(OR($AD11="",$AD11=0,$AC11=""),0,ROUND($AC11*$AD11*IFERROR(IF($R11="건별/비정기",$T11,VLOOKUP($R11,'04.코드표'!$K$5:$L$8,2,FALSE)*$S11),0)/60,1)) -> 0 | AJ11: =IF($L11="","",$AH11-$AI11) | AK11: =IF($L11="","",ROUND($AJ11/'04.코드표'!$L$11,2)) | AP11: =IF($L11="","",COUNTIFS($C$6:$C$62,$C11)) | AQ11: =IF($L11="","",IF($AP11=1,"⚠ 1개뿐 — 더 쪼개세요",IF($AP11=2,"△ 2개뿐 — 빠진 단계 확인",IF($AZ11<=2,"△ 하는 일이 "&$AZ11&"가지뿐 — 빠진 단계 확인","○ 좋음 (하는 일 "&$AZ11&"가지)")))) | AR11: =IF($L11="","",IF($BA11=0,"○ 다 채웠음","⚠ "&$BA11&"칸 비었음")) | AS11: =IF($L11="","",IF($BB11="","○ 문제 없음","⚠ "&LEFT($BB11,LEN($BB11)-3))) | AV11: =IF($L11="","",TRIM(RIGHT(SUBSTITUTE($AW11," ",REPT(" ",120)),120))) | AW11: =SUBSTITUTE($L11,CHAR(10)," ") | AX11: =SUBSTITUTE($J11,CHAR(10)," ") -> 자료/데이터 요청 | AY11: =IF($L11="","",IF(SUMPRODUCT(--ISNUMBER(SEARCH({"조회","수집","추출","검색","파악","취합","조달","접수","연계","연동","선별","확보","입수","조사","식별","검출","감지","스크랩","필터링"},$AV11)))>0,"조회",IF(SUMPRODUCT(--ISNUMBER(SEARCH({"검토","검증","판정","판별","확인","승인","선정","대조","점검","분류","확정","평가","판단","심사","검수","비교","결정","구분","진단","판독","협의"},$AV11)))>0,"검증",IF(SUMPRODUCT(--ISNUMBER(SEARCH({"등록","발송","배포","제출","보고","이관","업로드","비치","공유","통보","알림","축적","저장","안내","제시","전달","회신","게시","기록","전파","제공","공지","요청","지시","배정","회부"},$AV11)))>0,"등록",IF(SUMPRODUCT(--ISNUMBER(SEARCH({"작성","생성","산출","제작","입력","정리","집계","분석","정형화","도출","보정","구성","정렬","반영","수립","설계","보완","요약","번역","정의","산정","갱신","수정","편성","설정","누적","가공","변환","시각화","편집","통합","부여","정제","기입","조정","제거","표시","채번"},$AV11)))>0,"작성","기타"))))) | AZ11: =IF($L11="","",(COUNTIFS($C$6:$C$62,$C11,$AY$6:$AY$62,"조회")>0)+(COUNTIFS($C$6:$C$62,$C11,$AY$6:$AY$62,"작성")>0)+(COUNTIFS($C$6:$C$62,$C11,$AY$6:$AY$62,"검증")>0)+(COUNTIFS($C$6:$C$62,$C11,$AY$6:$AY$62,"등록")>0)) | BA11: =IF($L11="",0,IF($X11="신설",0,COUNTBLANK($N11)+COUNTBLANK($P11)+COUNTBLANK($Q11)+COUNTBLANK($R11)+IF($R11="건별/비정기",COUNTBLANK($T11),IF($R11="",0,COUNTBLANK($S11))))+IF($X11="삭제",0,COUNTBLANK($AC11)+COUNTBLANK($AD11))) -> 0 | BB11: =IF($L11="","",IF(AND($AX11<>"",ISNUMBER(SEARCH($AX11,$AW11))),"L5 이름을 그대로 씀 · ","")&IF(AND($L11<>"",$L11=$Z11),"개선 후 설명이 똑같음 · ","")&IF(COUNTIFS($C$6:$C$62,$C11,$L$6:$L$62,$L11)>1,"같은 내용이 또 있음 · ","")&IF(AND($U11<>"",$U11=$V11),"필요 자료와 산출물이 같음 · ","")&IF(AND($C11=$C5,$V5<>"",$U11<>"",ISERROR(SEARCH(SUBSTITUTE($V5,CHAR(10)," "),SUBSTITUTE($U11,CHAR(10)," "))),ISERROR(SEARCH(SUBSTITUTE($U11,CHAR(10)," "),SUBSTITUTE($V5,CHAR(10)," ")))),"앞 산출물과 이어지지 않음 · ","")&IF(SUMPRODUCT(--ISNUMBER(SEARCH({"관리한다","처리한다","수행한다","진행한다"},$AW11)))>0,"뭉뚱그린 동사 · ","")&IF(ISNUMBER(SEARCH("하고 ",$AW11)),"한 줄에 동작 2개 · ","")&IF(RIGHT($L11,2)<>"한다","~한다 로 안 끝남 · ","")&IF(AND($P11<>"",N($P11)>60),"1건 60분 넘음 — 더 쪼개세요 · ","")&IF(AND($AA11="AI",$AD11<>"",N($AD11)>0),"AI 혼자 하는데 사람 인원 있음 · ","")&IF(AND($AA11="AI+사람",$AD11<>"",N($AD11)=0),"사람이 확인한다는데 인원 0 · ","")&IF(AND($X11="유지",$Y11="AI"),"그대로 두는데 AI 를 쓴다고 함 · ","")&IF(AND($X11="신설",COUNT($P11,$Q11)>0),"새로 생기는 일인데 현재 공수가 있음 · ","")&IF(AND($X11="삭제",COUNT($AC11,$AD11)>0),"없애는 일인데 개선 후 공수가 있음 · ","")&IF(AND($X11<>"신설",N($AH11)>0,N($AI11)>N($AH11)),"개선 후가 지금보다 더 오래 걸림 · ","")) | BC11: =IFERROR(IF($L11="",0,1/$AP11),0) -> 0
B12: 7 | C12: 1.1.3.4.1 | D12: #4 | E12: 시큐리티 | F12: 마케팅 | G12: Market Intelligence | H12: MI 정보분석 및 시사점 도출 | I12: 기술 환경 분석 | J12: 기술 환경 분석 | K12: =IF($L12="","",$C12&"-"&TEXT(COUNTIFS($C$6:$C12,$C12),"00")) -> 1.1.3.4.1-01 | L12: 수집·선별된 자료에서 기술 환경 관련 정보를 추출한다 | N12: 사람 | P12: 25 | Q12: 1 | R12: 일 | S12: 1 | T12: 0 | U12: 1차 선별 자료, 국내외 기술전 정보 | V12: 기술 환경 관련 정보 | W12: 외부 | X12: 변경 | Y12: AI | Z12: AI가 선별 자료에서 기술 환경 관련 항목을 자동 추출해 분석 입력으로 정리한다 | AA12: AI | AE12: 1차 선별 자료, 국내외 기술전 정보 | AF12: 기술 환경 관련 정보 | AG12: AI Agent DB | AH12: =IF(OR($Q12="",$Q12=0,$P12=""),0,ROUND($P12*$Q12*IFERROR(IF($R12="건별/비정기",$T12,VLOOKUP($R12,'04.코드표'!$K$5:$L$8,2,FALSE)*$S12),0)/60,1)) -> 104.2 | AI12: =IF(OR($AD12="",$AD12=0,$AC12=""),0,ROUND($AC12*$AD12*IFERROR(IF($R12="건별/비정기",$T12,VLOOKUP($R12,'04.코드표'!$K$5:$L$8,2,FALSE)*$S12),0)/60,1)) -> 0 | AJ12: =IF($L12="","",$AH12-$AI12) -> 104.2 | AK12: =IF($L12="","",ROUND($AJ12/'04.코드표'!$L$11,2)) -> 0.05 | AL12: 하 | AM12: 분석에 쓸 내용을 자료 더미에서 사람이 골라내야 한다 | AP12: =IF($L12="","",COUNTIFS($C$6:$C$62,$C12)) -> 4 | AQ12: =IF($L12="","",IF($AP12=1,"⚠ 1개뿐 — 더 쪼개세요",IF($AP12=2,"△ 2개뿐 — 빠진 단계 확인",IF($AZ12<=2,"△ 하는 일이 "&$AZ12&"가지뿐 — 빠진 단계 확인","○ 좋음 (하는 일 "&$AZ12&"가지)")))) -> ○ 좋음 (하는 일 3가지) | AR12: =IF($L12="","",IF($BA12=0,"○ 다 채웠음","⚠ "&$BA12&"칸 비었음")) -> ⚠ 2칸 비었음 | AS12: =IF($L12="","",IF($BB12="","○ 문제 없음","⚠ "&LEFT($BB12,LEN($BB12)-3))) -> ○ 문제 없음 | AV12: =IF($L12="","",TRIM(RIGHT(SUBSTITUTE($AW12," ",REPT(" ",120)),120))) -> 추출한다 | AW12: =SUBSTITUTE($L12,CHAR(10)," ") -> 수집·선별된 자료에서 기술 환경 관련 정보를 추출한다 | AX12: =SUBSTITUTE($J12,CHAR(10)," ") -> 기술 환경 분석 | AY12: =IF($L12="","",IF(SUMPRODUCT(--ISNUMBER(SEARCH({"조회","수집","추출","검색","파악","취합","조달","접수","연계","연동","선별","확보","입수","조사","식별","검출","감지","스크랩","필터링"},$AV12)))>0,"조회",IF(SUMPRODUCT(--ISNUMBER(SEARCH({"검토","검증","판정","판별","확인","승인","선정","대조","점검","분류","확정","평가","판단","심사","검수","비교","결정","구분","진단","판독","협의"},$AV12)))>0,"검증",IF(SUMPRODUCT(--ISNUMBER(SEARCH({"등록","발송","배포","제출","보고","이관","업로드","비치","공유","통보","알림","축적","저장","안내","제시","전달","회신","게시","기록","전파","제공","공지","요청","지시","배정","회부"},$AV12)))>0,"등록",IF(SUMPRODUCT(--ISNUMBER(SEARCH({"작성","생성","산출","제작","입력","정리","집계","분석","정형화","도출","보정","구성","정렬","반영","수립","설계","보완","요약","번역","정의","산정","갱신","수정","편성","설정","누적","가공","변환","시각화","편집","통합","부여","정제","기입","조정","제거","표시","채번"},$AV12)))>0,"작성","기타"))))) -> 조회 | AZ12: =IF($L12="","",(COUNTIFS($C$6:$C$62,$C12,$AY$6:$AY$62,"조회")>0)+(COUNTIFS($C$6:$C$62,$C12,$AY$6:$AY$62,"작성")>0)+(COUNTIFS($C$6:$C$62,$C12,$AY$6:$AY$62,"검증")>0)+(COUNTIFS($C$6:$C$62,$C12,$AY$6:$AY$62,"등록")>0)) -> 3 | BA12: =IF($L12="",0,IF($X12="신설",0,COUNTBLANK($N12)+COUNTBLANK($P12)+COUNTBLANK($Q12)+COUNTBLANK($R12)+IF($R12="건별/비정기",COUNTBLANK($T12),IF($R12="",0,COUNTBLANK($S12))))+IF($X12="삭제",0,COUNTBLANK($AC12)+COUNTBLANK($AD12))) -> 2 | BB12: =IF($L12="","",IF(AND($AX12<>"",ISNUMBER(SEARCH($AX12,$AW12))),"L5 이름을 그대로 씀 · ","")&IF(AND($L12<>"",$L12=$Z12),"개선 후 설명이 똑같음 · ","")&IF(COUNTIFS($C$6:$C$62,$C12,$L$6:$L$62,$L12)>1,"같은 내용이 또 있음 · ","")&IF(AND($U12<>"",$U12=$V12),"필요 자료와 산출물이 같음 · ","")&IF(AND($C12=$C5,$V5<>"",$U12<>"",ISERROR(SEARCH(SUBSTITUTE($V5,CHAR(10)," "),SUBSTITUTE($U12,CHAR(10)," "))),ISERROR(SEARCH(SUBSTITUTE($U12,CHAR(10)," "),SUBSTITUTE($V5,CHAR(10)," ")))),"앞 산출물과 이어지지 않음 · ","")&IF(SUMPRODUCT(--ISNUMBER(SEARCH({"관리한다","처리한다","수행한다","진행한다"},$AW12)))>0,"뭉뚱그린 동사 · ","")&IF(ISNUMBER(SEARCH("하고 ",$AW12)),"한 줄에 동작 2개 · ","")&IF(RIGHT($L12,2)<>"한다","~한다 로 안 끝남 · ","")&IF(AND($P12<>"",N($P12)>60),"1건 60분 넘음 — 더 쪼개세요 · ","")&IF(AND($AA12="AI",$AD12<>"",N($AD12)>0),"AI 혼자 하는데 사람 인원 있음 · ","")&IF(AND($AA12="AI+사람",$AD12<>"",N($AD12)=0),"사람이 확인한다는데 인원 0 · ","")&IF(AND($X12="유지",$Y12="AI"),"그대로 두는데 AI 를 쓴다고 함 · ","")&IF(AND($X12="신설",COUNT($P12,$Q12)>0),"새로 생기는 일인데 현재 공수가 있음 · ","")&IF(AND($X12="삭제",COUNT($AC12,$AD12)>0),"없애는 일인데 개선 후 공수가 있음 · ","")&IF(AND($X12<>"신설",N($AH12)>0,N($AI12)>N($AH12)),"개선 후가 지금보다 더 오래 걸림 · ","")) | BC12: =IFERROR(IF($L12="",0,1/$AP12),0) -> 0.25
B13: 8 | C13: 1.1.3.4.1 | D13: #4 | E13: 시큐리티 | F13: 마케팅 | G13: Market Intelligence | H13: MI 정보분석 및 시사점 도출 | I13: 기술 환경 분석 | J13: 기술 환경 분석 | K13: =IF($L13="","",$C13&"-"&TEXT(COUNTIFS($C$6:$C13,$C13),"00")) -> 1.1.3.4.1-02 | L13: 외부 기술 변화가 내부 기술 역량과 시스템에 미치는 영향을 분석한다 | N13: 사람 | P13: 5 | Q13: 1 | R13: 일 | S13: 1 | T13: 0 | U13: 기술 환경 관련 정보 | V13: 기술 환경 분석 결과 | W13: offline(개인PC) | X13: 변경 | Y13: AI | Z13: 기술/인프라 관점 에이전트가 내부 역량·시스템 영향 관점의 분석안을 제시한다 | AA13: AI+사람 | AE13: 기술 환경 관련 정보 | AF13: 기술 환경 분석 결과 | AG13: AI Agent DB | AH13: =IF(OR($Q13="",$Q13=0,$P13=""),0,ROUND($P13*$Q13*IFERROR(IF($R13="건별/비정기",$T13,VLOOKUP($R13,'04.코드표'!$K$5:$L$8,2,FALSE)*$S13),0)/60,1)) -> 20.8 | AI13: =IF(OR($AD13="",$AD13=0,$AC13=""),0,ROUND($AC13*$AD13*IFERROR(IF($R13="건별/비정기",$T13,VLOOKUP($R13,'04.코드표'!$K$5:$L$8,2,FALSE)*$S13),0)/60,1)) -> 0 | AJ13: =IF($L13="","",$AH13-$AI13) -> 20.8 | AK13: =IF($L13="","",ROUND($AJ13/'04.코드표'!$L$11,2)) -> 0.01 | AL13: 상 | AM13: 분석 관점이 담당자 개인의 시각에 한정되어 놓치는 영역이 생긴다 | AP13: =IF($L13="","",COUNTIFS($C$6:$C$62,$C13)) -> 4 | AQ13: =IF($L13="","",IF($AP13=1,"⚠ 1개뿐 — 더 쪼개세요",IF($AP13=2,"△ 2개뿐 — 빠진 단계 확인",IF($AZ13<=2,"△ 하는 일이 "&$AZ13&"가지뿐 — 빠진 단계 확인","○ 좋음 (하는 일 "&$AZ13&"가지)")))) -> ○ 좋음 (하는 일 3가지) | AR13: =IF($L13="","",IF($BA13=0,"○ 다 채웠음","⚠ "&$BA13&"칸 비었음")) -> ⚠ 2칸 비었음 | AS13: =IF($L13="","",IF($BB13="","○ 문제 없음","⚠ "&LEFT($BB13,LEN($BB13)-3))) -> ○ 문제 없음 | AV13: =IF($L13="","",TRIM(RIGHT(SUBSTITUTE($AW13," ",REPT(" ",120)),120))) -> 분석한다 | AW13: =SUBSTITUTE($L13,CHAR(10)," ") -> 외부 기술 변화가 내부 기술 역량과 시스템에 미치는 영향을 분석한다 | AX13: =SUBSTITUTE($J13,CHAR(10)," ") -> 기술 환경 분석 | AY13: =IF($L13="","",IF(SUMPRODUCT(--ISNUMBER(SEARCH({"조회","수집","추출","검색","파악","취합","조달","접수","연계","연동","선별","확보","입수","조사","식별","검출","감지","스크랩","필터링"},$AV13)))>0,"조회",IF(SUMPRODUCT(--ISNUMBER(SEARCH({"검토","검증","판정","판별","확인","승인","선정","대조","점검","분류","확정","평가","판단","심사","검수","비교","결정","구분","진단","판독","협의"},$AV13)))>0,"검증",IF(SUMPRODUCT(--ISNUMBER(SEARCH({"등록","발송","배포","제출","보고","이관","업로드","비치","공유","통보","알림","축적","저장","안내","제시","전달","회신","게시","기록","전파","제공","공지","요청","지시","배정","회부"},$AV13)))>0,"등록",IF(SUMPRODUCT(--ISNUMBER(SEARCH({"작성","생성","산출","제작","입력","정리","집계","분석","정형화","도출","보정","구성","정렬","반영","수립","설계","보완","요약","번역","정의","산정","갱신","수정","편성","설정","누적","가공","변환","시각화","편집","통합","부여","정제","기입","조정","제거","표시","채번"},$AV13)))>0,"작성","기타"))))) -> 작성 | AZ13: =IF($L13="","",(COUNTIFS($C$6:$C$62,$C13,$AY$6:$AY$62,"조회")>0)+(COUNTIFS($C$6:$C$62,$C13,$AY$6:$AY$62,"작성")>0)+(COUNTIFS($C$6:$C$62,$C13,$AY$6:$AY$62,"검증")>0)+(COUNTIFS($C$6:$C$62,$C13,$AY$6:$AY$62,"등록")>0)) -> 3 | BA13: =IF($L13="",0,IF($X13="신설",0,COUNTBLANK($N13)+COUNTBLANK($P13)+COUNTBLANK($Q13)+COUNTBLANK($R13)+IF($R13="건별/비정기",COUNTBLANK($T13),IF($R13="",0,COUNTBLANK($S13))))+IF($X13="삭제",0,COUNTBLANK($AC13)+COUNTBLANK($AD13))) -> 2 | BB13: =IF($L13="","",IF(AND($AX13<>"",ISNUMBER(SEARCH($AX13,$AW13))),"L5 이름을 그대로 씀 · ","")&IF(AND($L13<>"",$L13=$Z13),"개선 후 설명이 똑같음 · ","")&IF(COUNTIFS($C$6:$C$62,$C13,$L$6:$L$62,$L13)>1,"같은 내용이 또 있음 · ","")&IF(AND($U13<>"",$U13=$V13),"필요 자료와 산출물이 같음 · ","")&IF(AND($C13=$C5,$V5<>"",$U13<>"",ISERROR(SEARCH(SUBSTITUTE($V5,CHAR(10)," "),SUBSTITUTE($U13,CHAR(10)," "))),ISERROR(SEARCH(SUBSTITUTE($U13,CHAR(10)," "),SUBSTITUTE($V5,CHAR(10)," ")))),"앞 산출물과 이어지지 않음 · ","")&IF(SUMPRODUCT(--ISNUMBER(SEARCH({"관리한다","처리한다","수행한다","진행한다"},$AW13)))>0,"뭉뚱그린 동사 · ","")&IF(ISNUMBER(SEARCH("하고 ",$AW13)),"한 줄에 동작 2개 · ","")&IF(RIGHT($L13,2)<>"한다","~한다 로 안 끝남 · ","")&IF(AND($P13<>"",N($P13)>60),"1건 60분 넘음 — 더 쪼개세요 · ","")&IF(AND($AA13="AI",$AD13<>"",N($AD13)>0),"AI 혼자 하는데 사람 인원 있음 · ","")&IF(AND($AA13="AI+사람",$AD13<>"",N($AD13)=0),"사람이 확인한다는데 인원 0 · ","")&IF(AND($X13="유지",$Y13="AI"),"그대로 두는데 AI 를 쓴다고 함 · ","")&IF(AND($X13="신설",COUNT($P13,$Q13)>0),"새로 생기는 일인데 현재 공수가 있음 · ","")&IF(AND($X13="삭제",COUNT($AC13,$AD13)>0),"없애는 일인데 개선 후 공수가 있음 · ","")&IF(AND($X13<>"신설",N($AH13)>0,N($AI13)>N($AH13)),"개선 후가 지금보다 더 오래 걸림 · ","")) | BC13: =IFERROR(IF($L13="",0,1/$AP13),0) -> 0.25
B14: 9 | C14: 1.1.3.4.1 | D14: #4 | E14: 시큐리티 | F14: 마케팅 | G14: Market Intelligence | H14: MI 정보분석 및 시사점 도출 | I14: 기술 환경 분석 | J14: 기술 환경 분석 | K14: =IF($L14="","",$C14&"-"&TEXT(COUNTIFS($C$6:$C14,$C14),"00")) -> 1.1.3.4.1-03 | L14: 분석에 필요한 통계 수치를 표·이미지로 시각화한다 | N14: 사람 | P14: 15 | Q14: 1 | R14: 주 | S14: 1 | T14: 0 | U14: 기술 환경 분석 결과, 통계 자료 | V14: 표·이미지 시각화 자료 | W14: offline(개인PC) | X14: 변경 | Y14: AI | Z14: 수치 보완과 표·이미지 제작이 자동화되어 분석가는 해석에 집중한다 | AA14: AI | AE14: 기술 환경 분석 결과, 통계 자료 | AF14: 표·이미지 시각화 자료 | AG14: AI Agent DB | AH14: =IF(OR($Q14="",$Q14=0,$P14=""),0,ROUND($P14*$Q14*IFERROR(IF($R14="건별/비정기",$T14,VLOOKUP($R14,'04.코드표'!$K$5:$L$8,2,FALSE)*$S14),0)/60,1)) -> 13 | AI14: =IF(OR($AD14="",$AD14=0,$AC14=""),0,ROUND($AC14*$AD14*IFERROR(IF($R14="건별/비정기",$T14,VLOOKUP($R14,'04.코드표'!$K$5:$L$8,2,FALSE)*$S14),0)/60,1)) -> 0 | AJ14: =IF($L14="","",$AH14-$AI14) -> 13 | AK14: =IF($L14="","",ROUND($AJ14/'04.코드표'!$L$11,2)) -> 0.01 | AL14: 하 | AM14: 수치 보완과 표·이미지 제작에 분석가 시간이 과도하게 소모된다 | AP14: =IF($L14="","",COUNTIFS($C$6:$C$62,$C14)) -> 4 | AQ14: =IF($L14="","",IF($AP14=1,"⚠ 1개뿐 — 더 쪼개세요",IF($AP14=2,"△ 2개뿐 — 빠진 단계 확인",IF($AZ14<=2,"△ 하는 일이 "&$AZ14&"가지뿐 — 빠진 단계 확인","○ 좋음 (하는 일 "&$AZ14&"가지)")))) -> ○ 좋음 (하는 일 3가지) | AR14: =IF($L14="","",IF($BA14=0,"○ 다 채웠음","⚠ "&$BA14&"칸 비었음")) -> ⚠ 2칸 비었음 | AS14: =IF($L14="","",IF($BB14="","○ 문제 없음","⚠ "&LEFT($BB14,LEN($BB14)-3))) -> ○ 문제 없음 | AV14: =IF($L14="","",TRIM(RIGHT(SUBSTITUTE($AW14," ",REPT(" ",120)),120))) -> 시각화한다 | AW14: =SUBSTITUTE($L14,CHAR(10)," ") -> 분석에 필요한 통계 수치를 표·이미지로 시각화한다 | AX14: =SUBSTITUTE($J14,CHAR(10)," ") -> 기술 환경 분석 | AY14: =IF($L14="","",IF(SUMPRODUCT(--ISNUMBER(SEARCH({"조회","수집","추출","검색","파악","취합","조달","접수","연계","연동","선별","확보","입수","조사","식별","검출","감지","스크랩","필터링"},$AV14)))>0,"조회",IF(SUMPRODUCT(--ISNUMBER(SEARCH({"검토","검증","판정","판별","확인","승인","선정","대조","점검","분류","확정","평가","판단","심사","검수","비교","결정","구분","진단","판독","협의"},$AV14)))>0,"검증",IF(SUMPRODUCT(--ISNUMBER(SEARCH({"등록","발송","배포","제출","보고","이관","업로드","비치","공유","통보","알림","축적","저장","안내","제시","전달","회신","게시","기록","전파","제공","공지","요청","지시","배정","회부"},$AV14)))>0,"등록",IF(SUMPRODUCT(--ISNUMBER(SEARCH({"작성","생성","산출","제작","입력","정리","집계","분석","정형화","도출","보정","구성","정렬","반영","수립","설계","보완","요약","번역","정의","산정","갱신","수정","편성","설정","누적","가공","변환","시각화","편집","통합","부여","정제","기입","조정","제거","표시","채번"},$AV14)))>0,"작성","기타"))))) -> 작성 | AZ14: =IF($L14="","",(COUNTIFS($C$6:$C$62,$C14,$AY$6:$AY$62,"조회")>0)+(COUNTIFS($C$6:$C$62,$C14,$AY$6:$AY$62,"작성")>0)+(COUNTIFS($C$6:$C$62,$C14,$AY$6:$AY$62,"검증")>0)+(COUNTIFS($C$6:$C$62,$C14,$AY$6:$AY$62,"등록")>0)) -> 3 | BA14: =IF($L14="",0,IF($X14="신설",0,COUNTBLANK($N14)+COUNTBLANK($P14)+COUNTBLANK($Q14)+COUNTBLANK($R14)+IF($R14="건별/비정기",COUNTBLANK($T14),IF($R14="",0,COUNTBLANK($S14))))+IF($X14="삭제",0,COUNTBLANK($AC14)+COUNTBLANK($AD14))) -> 2 | BB14: =IF($L14="","",IF(AND($AX14<>"",ISNUMBER(SEARCH($AX14,$AW14))),"L5 이름을 그대로 씀 · ","")&IF(AND($L14<>"",$L14=$Z14),"개선 후 설명이 똑같음 · ","")&IF(COUNTIFS($C$6:$C$62,$C14,$L$6:$L$62,$L14)>1,"같은 내용이 또 있음 · ","")&IF(AND($U14<>"",$U14=$V14),"필요 자료와 산출물이 같음 · ","")&IF(AND($C14=$C5,$V5<>"",$U14<>"",ISERROR(SEARCH(SUBSTITUTE($V5,CHAR(10)," "),SUBSTITUTE($U14,CHAR(10)," "))),ISERROR(SEARCH(SUBSTITUTE($U14,CHAR(10)," "),SUBSTITUTE($V5,CHAR(10)," ")))),"앞 산출물과 이어지지 않음 · ","")&IF(SUMPRODUCT(--ISNUMBER(SEARCH({"관리한다","처리한다","수행한다","진행한다"},$AW14)))>0,"뭉뚱그린 동사 · ","")&IF(ISNUMBER(SEARCH("하고 ",$AW14)),"한 줄에 동작 2개 · ","")&IF(RIGHT($L14,2)<>"한다","~한다 로 안 끝남 · ","")&IF(AND($P14<>"",N($P14)>60),"1건 60분 넘음 — 더 쪼개세요 · ","")&IF(AND($AA14="AI",$AD14<>"",N($AD14)>0),"AI 혼자 하는데 사람 인원 있음 · ","")&IF(AND($AA14="AI+사람",$AD14<>"",N($AD14)=0),"사람이 확인한다는데 인원 0 · ","")&IF(AND($X14="유지",$Y14="AI"),"그대로 두는데 AI 를 쓴다고 함 · ","")&IF(AND($X14="신설",COUNT($P14,$Q14)>0),"새로 생기는 일인데 현재 공수가 있음 · ","")&IF(AND($X14="삭제",COUNT($AC14,$AD14)>0),"없애는 일인데 개선 후 공수가 있음 · ","")&IF(AND($X14<>"신설",N($AH14)>0,N($AI14)>N($AH14)),"개선 후가 지금보다 더 오래 걸림 · ","")) | BC14: =IFERROR(IF($L14="",0,1/$AP14),0) -> 0.25
B15: 10 | C15: 1.1.3.4.1 | D15: #4 | E15: 시큐리티 | F15: 마케팅 | G15: Market Intelligence | H15: MI 정보분석 및 시사점 도출 | I15: 기술 환경 분석 | J15: 기술 환경 분석 | K15: =IF($L15="","",$C15&"-"&TEXT(COUNTIFS($C$6:$C15,$C15),"00")) -> 1.1.3.4.1-04 | L15: 분석 결과의 타당성을 검토하여 채택 여부를 결정한다 | M15: 제시된 분석 내용이 근거 자료로 뒷받침되는지 여부 | N15: 사람 | P15: 5 | Q15: 1 | R15: 주 | S15: 1 | T15: 0 | U15: 기술 환경 분석 결과, 표·이미지 시각화 자료 | V15: 확정된 기술 환경 분석 | W15: offline(개인PC) | X15: 변경 | Y15: AI | Z15: AI 분석안에 대해 사람이 최종 채택·기각을 표시하고 그 판단이 기록으로 남는다 | AA15: 사람 | AE15: 기술 환경 분석 결과, 표·이미지 시각화 자료 | AF15: 확정된 기술 환경 분석 | AG15: AI Agent DB | AH15: =IF(OR($Q15="",$Q15=0,$P15=""),0,ROUND($P15*$Q15*IFERROR(IF($R15="건별/비정기",$T15,VLOOKUP($R15,'04.코드표'!$K$5:$L$8,2,FALSE)*$S15),0)/60,1)) -> 4.3 | AI15: =IF(OR($AD15="",$AD15=0,$AC15=""),0,ROUND($AC15*$AD15*IFERROR(IF($R15="건별/비정기",$T15,VLOOKUP($R15,'04.코드표'!$K$5:$L$8,2,FALSE)*$S15),0)/60,1)) -> 0 | AJ15: =IF($L15="","",$AH15-$AI15) -> 4.3 | AK15: =IF($L15="","",ROUND($AJ15/'04.코드표'!$L$11,2)) -> 0 | AL15: 상 | AM15: 검토 기준이 명문화돼 있지 않아 결과 품질이 담당자에 따라 달라진다 | AP15: =IF($L15="","",COUNTIFS($C$6:$C$62,$C15)) -> 4 | AQ15: =IF($L15="","",IF($AP15=1,"⚠ 1개뿐 — 더 쪼개세요",IF($AP15=2,"△ 2개뿐 — 빠진 단계 확인",IF($AZ15<=2,"△ 하는 일이 "&$AZ15&"가지뿐 — 빠진 단계 확인","○ 좋음 (하는 일 "&$AZ15&"가지)")))) -> ○ 좋음 (하는 일 3가지) | AR15: =IF($L15="","",IF($BA15=0,"○ 다 채웠음","⚠ "&$BA15&"칸 비었음")) -> ⚠ 2칸 비었음 | AS15: =IF($L15="","",IF($BB15="","○ 문제 없음","⚠ "&LEFT($BB15,LEN($BB15)-3))) -> ○ 문제 없음 | AV15: =IF($L15="","",TRIM(RIGHT(SUBSTITUTE($AW15," ",REPT(" ",120)),120))) -> 결정한다 | AW15: =SUBSTITUTE($L15,CHAR(10)," ") -> 분석 결과의 타당성을 검토하여 채택 여부를 결정한다 | AX15: =SUBSTITUTE($J15,CHAR(10)," ") -> 기술 환경 분석 | AY15: =IF($L15="","",IF(SUMPRODUCT(--ISNUMBER(SEARCH({"조회","수집","추출","검색","파악","취합","조달","접수","연계","연동","선별","확보","입수","조사","식별","검출","감지","스크랩","필터링"},$AV15)))>0,"조회",IF(SUMPRODUCT(--ISNUMBER(SEARCH({"검토","검증","판정","판별","확인","승인","선정","대조","점검","분류","확정","평가","판단","심사","검수","비교","결정","구분","진단","판독","협의"},$AV15)))>0,"검증",IF(SUMPRODUCT(--ISNUMBER(SEARCH({"등록","발송","배포","제출","보고","이관","업로드","비치","공유","통보","알림","축적","저장","안내","제시","전달","회신","게시","기록","전파","제공","공지","요청","지시","배정","회부"},$AV15)))>0,"등록",IF(SUMPRODUCT(--ISNUMBER(SEARCH({"작성","생성","산출","제작","입력","정리","집계","분석","정형화","도출","보정","구성","정렬","반영","수립","설계","보완","요약","번역","정의","산정","갱신","수정","편성","설정","누적","가공","변환","시각화","편집","통합","부여","정제","기입","조정","제거","표시","채번"},$AV15)))>0,"작성","기타"))))) -> 검증 | AZ15: =IF($L15="","",(COUNTIFS($C$6:$C$62,$C15,$AY$6:$AY$62,"조회")>0)+(COUNTIFS($C$6:$C$62,$C15,$AY$6:$AY$62,"작성")>0)+(COUNTIFS($C$6:$C$62,$C15,$AY$6:$AY$62,"검증")>0)+(COUNTIFS($C$6:$C$62,$C15,$AY$6:$AY$62,"등록")>0)) -> 3 | BA15: =IF($L15="",0,IF($X15="신설",0,COUNTBLANK($N15)+COUNTBLANK($P15)+COUNTBLANK($Q15)+COUNTBLANK($R15)+IF($R15="건별/비정기",COUNTBLANK($T15),IF($R15="",0,COUNTBLANK($S15))))+IF($X15="삭제",0,COUNTBLANK($AC15)+COUNTBLANK($AD15))) -> 2 | BB15: =IF($L15="","",IF(AND($AX15<>"",ISNUMBER(SEARCH($AX15,$AW15))),"L5 이름을 그대로 씀 · ","")&IF(AND($L15<>"",$L15=$Z15),"개선 후 설명이 똑같음 · ","")&IF(COUNTIFS($C$6:$C$62,$C15,$L$6:$L$62,$L15)>1,"같은 내용이 또 있음 · ","")&IF(AND($U15<>"",$U15=$V15),"필요 자료와 산출물이 같음 · ","")&IF(AND($C15=$C5,$V5<>"",$U15<>"",ISERROR(SEARCH(SUBSTITUTE($V5,CHAR(10)," "),SUBSTITUTE($U15,CHAR(10)," "))),ISERROR(SEARCH(SUBSTITUTE($U15,CHAR(10)," "),SUBSTITUTE($V5,CHAR(10)," ")))),"앞 산출물과 이어지지 않음 · ","")&IF(SUMPRODUCT(--ISNUMBER(SEARCH({"관리한다","처리한다","수행한다","진행한다"},$AW15)))>0,"뭉뚱그린 동사 · ","")&IF(ISNUMBER(SEARCH("하고 ",$AW15)),"한 줄에 동작 2개 · ","")&IF(RIGHT($L15,2)<>"한다","~한다 로 안 끝남 · ","")&IF(AND($P15<>"",N($P15)>60),"1건 60분 넘음 — 더 쪼개세요 · ","")&IF(AND($AA15="AI",$AD15<>"",N($AD15)>0),"AI 혼자 하는데 사람 인원 있음 · ","")&IF(AND($AA15="AI+사람",$AD15<>"",N($AD15)=0),"사람이 확인한다는데 인원 0 · ","")&IF(AND($X15="유지",$Y15="AI"),"그대로 두는데 AI 를 쓴다고 함 · ","")&IF(AND($X15="신설",COUNT($P15,$Q15)>0),"새로 생기는 일인데 현재 공수가 있음 · ","")&IF(AND($X15="삭제",COUNT($AC15,$AD15)>0),"없애는 일인데 개선 후 공수가 있음 · ","")&IF(AND($X15<>"신설",N($AH15)>0,N($AI15)>N($AH15)),"개선 후가 지금보다 더 오래 걸림 · ","")) | BC15: =IFERROR(IF($L15="",0,1/$AP15),0) -> 0.25
B16: 11 | C16: 1.1.3.5.1 | D16: #4 | E16: 시큐리티 | F16: 마케팅 | G16: Market Intelligence | H16: MI 정보분석 및 시사점 도출 | I16: 시사점 도출 | J16: 환경분석 시사점도출 | K16: =IF($L16="","",$C16&"-"&TEXT(COUNTIFS($C$6:$C16,$C16),"00")) -> 1.1.3.5.1-01 | L16: 정치·경제·사회·기술 환경 분석 결과를 조회한다 | N16: 사람 | P16: 25 | Q16: 1 | R16: 주 | S16: 1 | T16: 0 | U16: 확정된 환경 분석 결과 | V16: 환경 분석 종합 자료 | W16: offline(개인PC) | X16: 변경 | Y16: AI | Z16: 환경별 분석 결과가 하나의 입력으로 자동 취합되어 시사점 도출 단계로 전달된다 | AA16: AI | AE16: 확정된 환경 분석 결과 | AF16: 환경 분석 종합 자료 | AG16: AI Agent DB | AH16: =IF(OR($Q16="",$Q16=0,$P16=""),0,ROUND($P16*$Q16*IFERROR(IF($R16="건별/비정기",$T16,VLOOKUP($R16,'04.코드표'!$K$5:$L$8,2,FALSE)*$S16),0)/60,1)) -> 21.7 | AI16: =IF(OR($AD16="",$AD16=0,$AC16=""),0,ROUND($AC16*$AD16*IFERROR(IF($R16="건별/비정기",$T16,VLOOKUP($R16,'04.코드표'!$K$5:$L$8,2,FALSE)*$S16),0)/60,1)) -> 0 | AJ16: =IF($L16="","",$AH16-$AI16) -> 21.7 | AK16: =IF($L16="","",ROUND($AJ16/'04.코드표'!$L$11,2)) -> 0.01 | AL16: 하 | AM16: 분석 결과가 문서별로 흩어져 있어 종합에 별도 정리 작업이 필요하다 | AP16: =IF($L16="","",COUNTIFS($C$6:$C$62,$C16)) -> 5 | AQ16: =IF($L16="","",IF($AP16=1,"⚠ 1개뿐 — 더 쪼개세요",IF($AP16=2,"△ 2개뿐 — 빠진 단계 확인",IF($AZ16<=2,"△ 하는 일이 "&$AZ16&"가지뿐 — 빠진 단계 확인","○ 좋음 (하는 일 "&$AZ16&"가지)")))) -> ○ 좋음 (하는 일 4가지) | AR16: =IF($L16="","",IF($BA16=0,"○ 다 채웠음","⚠ "&$BA16&"칸 비었음")) -> ⚠ 2칸 비었음 | AS16: =IF($L16="","",IF($BB16="","○ 문제 없음","⚠ "&LEFT($BB16,LEN($BB16)-3))) -> ○ 문제 없음 | AV16: =IF($L16="","",TRIM(RIGHT(SUBSTITUTE($AW16," ",REPT(" ",120)),120))) -> 조회한다 | AW16: =SUBSTITUTE($L16,CHAR(10)," ") -> 정치·경제·사회·기술 환경 분석 결과를 조회한다 | AX16: =SUBSTITUTE($J16,CHAR(10)," ") -> 환경분석 시사점도출 | AY16: =IF($L16="","",IF(SUMPRODUCT(--ISNUMBER(SEARCH({"조회","수집","추출","검색","파악","취합","조달","접수","연계","연동","선별","확보","입수","조사","식별","검출","감지","스크랩","필터링"},$AV16)))>0,"조회",IF(SUMPRODUCT(--ISNUMBER(SEARCH({"검토","검증","판정","판별","확인","승인","선정","대조","점검","분류","확정","평가","판단","심사","검수","비교","결정","구분","진단","판독","협의"},$AV16)))>0,"검증",IF(SUMPRODUCT(--ISNUMBER(SEARCH({"등록","발송","배포","제출","보고","이관","업로드","비치","공유","통보","알림","축적","저장","안내","제시","전달","회신","게시","기록","전파","제공","공지","요청","지시","배정","회부"},$AV16)))>0,"등록",IF(SUMPRODUCT(--ISNUMBER(SEARCH({"작성","생성","산출","제작","입력","정리","집계","분석","정형화","도출","보정","구성","정렬","반영","수립","설계","보완","요약","번역","정의","산정","갱신","수정","편성","설정","누적","가공","변환","시각화","편집","통합","부여","정제","기입","조정","제거","표시","채번"},$AV16)))>0,"작성","기타"))))) -> 조회 | AZ16: =IF($L16="","",(COUNTIFS($C$6:$C$62,$C16,$AY$6:$AY$62,"조회")>0)+(COUNTIFS($C$6:$C$62,$C16,$AY$6:$AY$62,"작성")>0)+(COUNTIFS($C$6:$C$62,$C16,$AY$6:$AY$62,"검증")>0)+(COUNTIFS($C$6:$C$62,$C16,$AY$6:$AY$62,"등록")>0)) -> 4 | BA16: =IF($L16="",0,IF($X16="신설",0,COUNTBLANK($N16)+COUNTBLANK($P16)+COUNTBLANK($Q16)+COUNTBLANK($R16)+IF($R16="건별/비정기",COUNTBLANK($T16),IF($R16="",0,COUNTBLANK($S16))))+IF($X16="삭제",0,COUNTBLANK($AC16)+COUNTBLANK($AD16))) -> 2 | BB16: =IF($L16="","",IF(AND($AX16<>"",ISNUMBER(SEARCH($AX16,$AW16))),"L5 이름을 그대로 씀 · ","")&IF(AND($L16<>"",$L16=$Z16),"개선 후 설명이 똑같음 · ","")&IF(COUNTIFS($C$6:$C$62,$C16,$L$6:$L$62,$L16)>1,"같은 내용이 또 있음 · ","")&IF(AND($U16<>"",$U16=$V16),"필요 자료와 산출물이 같음 · ","")&IF(AND($C16=$C5,$V5<>"",$U16<>"",ISERROR(SEARCH(SUBSTITUTE($V5,CHAR(10)," "),SUBSTITUTE($U16,CHAR(10)," "))),ISERROR(SEARCH(SUBSTITUTE($U16,CHAR(10)," "),SUBSTITUTE($V5,CHAR(10)," ")))),"앞 산출물과 이어지지 않음 · ","")&IF(SUMPRODUCT(--ISNUMBER(SEARCH({"관리한다","처리한다","수행한다","진행한다"},$AW16)))>0,"뭉뚱그린 동사 · ","")&IF(ISNUMBER(SEARCH("하고 ",$AW16)),"한 줄에 동작 2개 · ","")&IF(RIGHT($L16,2)<>"한다","~한다 로 안 끝남 · ","")&IF(AND($P16<>"",N($P16)>60),"1건 60분 넘음 — 더 쪼개세요 · ","")&IF(AND($AA16="AI",$AD16<>"",N($AD16)>0),"AI 혼자 하는데 사람 인원 있음 · ","")&IF(AND($AA16="AI+사람",$AD16<>"",N($AD16)=0),"사람이 확인한다는데 인원 0 · ","")&IF(AND($X16="유지",$Y16="AI"),"그대로 두는데 AI 를 쓴다고 함 · ","")&IF(AND($X16="신설",COUNT($P16,$Q16)>0),"새로 생기는 일인데 현재 공수가 있음 · ","")&IF(AND($X16="삭제",COUNT($AC16,$AD16)>0),"없애는 일인데 개선 후 공수가 있음 · ","")&IF(AND($X16<>"신설",N($AH16)>0,N($AI16)>N($AH16)),"개선 후가 지금보다 더 오래 걸림 · ","")) | BC16: =IFERROR(IF($L16="",0,1/$AP16),0) -> 0.2
B17: 12 | C17: 1.1.3.5.1 | D17: #4 | E17: 시큐리티 | F17: 마케팅 | G17: Market Intelligence | H17: MI 정보분석 및 시사점 도출 | I17: 시사점 도출 | J17: 환경분석 시사점도출 | K17: =IF($L17="","",$C17&"-"&TEXT(COUNTIFS($C$6:$C17,$C17),"00")) -> 1.1.3.5.1-02 | L17: 상품/서비스·영업/채널·기술/인프라·마케팅 4개 관점별로 시사점을 도출한다 | N17: 사람 | P17: 15 | Q17: 1 | R17: 주 | S17: 1 | T17: 0 | U17: 환경 분석 종합 자료, 관점별 역할 정의 | V17: 관점별 시사점 | W17: offline(개인PC) | X17: 신설 | Y17: AI | Z17: 4개 관점 에이전트가 각자의 시각에서 시사점을 동시에 도출해 다관점 결과를 제시한다 | AA17: AI | AE17: 환경 분석 종합 자료, 관점별 역할 정의 | AF17: 관점별 시사점 | AG17: AI Agent DB | AH17: =IF(OR($Q17="",$Q17=0,$P17=""),0,ROUND($P17*$Q17*IFERROR(IF($R17="건별/비정기",$T17,VLOOKUP($R17,'04.코드표'!$K$5:$L$8,2,FALSE)*$S17),0)/60,1)) -> 13 | AI17: =IF(OR($AD17="",$AD17=0,$AC17=""),0,ROUND($AC17*$AD17*IFERROR(IF($R17="건별/비정기",$T17,VLOOKUP($R17,'04.코드표'!$K$5:$L$8,2,FALSE)*$S17),0)/60,1)) -> 0 | AJ17: =IF($L17="","",$AH17-$AI17) -> 13 | AK17: =IF($L17="","",ROUND($AJ17/'04.코드표'!$L$11,2)) -> 0.01 | AL17: 상 | AM17: 인사이트 도출이 특정인의 암묵지에 의존해 관점이 한쪽으로 치우친다 | AP17: =IF($L17="","",COUNTIFS($C$6:$C$62,$C17)) -> 5 | AQ17: =IF($L17="","",IF($AP17=1,"⚠ 1개뿐 — 더 쪼개세요",IF($AP17=2,"△ 2개뿐 — 빠진 단계 확인",IF($AZ17<=2,"△ 하는 일이 "&$AZ17&"가지뿐 — 빠진 단계 확인","○ 좋음 (하는 일 "&$AZ17&"가지)")))) -> ○ 좋음 (하는 일 4가지) | AR17: =IF($L17="","",IF($BA17=0,"○ 다 채웠음","⚠ "&$BA17&"칸 비었음")) -> ⚠ 2칸 비었음 | AS17: =IF($L17="","",IF($BB17="","○ 문제 없음","⚠ "&LEFT($BB17,LEN($BB17)-3))) -> ⚠ 새로 생기는 일인데 현재 공수가 있음 | AV17: =IF($L17="","",TRIM(RIGHT(SUBSTITUTE($AW17," ",REPT(" ",120)),120))) -> 도출한다 | AW17: =SUBSTITUTE($L17,CHAR(10)," ") -> 상품/서비스·영업/채널·기술/인프라·마케팅 4개 관점별로 시사점을 도출한다 | AX17: =SUBSTITUTE($J17,CHAR(10)," ") -> 환경분석 시사점도출 | AY17: =IF($L17="","",IF(SUMPRODUCT(--ISNUMBER(SEARCH({"조회","수집","추출","검색","파악","취합","조달","접수","연계","연동","선별","확보","입수","조사","식별","검출","감지","스크랩","필터링"},$AV17)))>0,"조회",IF(SUMPRODUCT(--ISNUMBER(SEARCH({"검토","검증","판정","판별","확인","승인","선정","대조","점검","분류","확정","평가","판단","심사","검수","비교","결정","구분","진단","판독","협의"},$AV17)))>0,"검증",IF(SUMPRODUCT(--ISNUMBER(SEARCH({"등록","발송","배포","제출","보고","이관","업로드","비치","공유","통보","알림","축적","저장","안내","제시","전달","회신","게시","기록","전파","제공","공지","요청","지시","배정","회부"},$AV17)))>0,"등록",IF(SUMPRODUCT(--ISNUMBER(SEARCH({"작성","생성","산출","제작","입력","정리","집계","분석","정형화","도출","보정","구성","정렬","반영","수립","설계","보완","요약","번역","정의","산정","갱신","수정","편성","설정","누적","가공","변환","시각화","편집","통합","부여","정제","기입","조정","제거","표시","채번"},$AV17)))>0,"작성","기타"))))) -> 작성 | AZ17: =IF($L17="","",(COUNTIFS($C$6:$C$62,$C17,$AY$6:$AY$62,"조회")>0)+(COUNTIFS($C$6:$C$62,$C17,$AY$6:$AY$62,"작성")>0)+(COUNTIFS($C$6:$C$62,$C17,$AY$6:$AY$62,"검증")>0)+(COUNTIFS($C$6:$C$62,$C17,$AY$6:$AY$62,"등록")>0)) -> 4 | BA17: =IF($L17="",0,IF($X17="신설",0,COUNTBLANK($N17)+COUNTBLANK($P17)+COUNTBLANK($Q17)+COUNTBLANK($R17)+IF($R17="건별/비정기",COUNTBLANK($T17),IF($R17="",0,COUNTBLANK($S17))))+IF($X17="삭제",0,COUNTBLANK($AC17)+COUNTBLANK($AD17))) -> 2 | BB17: =IF($L17="","",IF(AND($AX17<>"",ISNUMBER(SEARCH($AX17,$AW17))),"L5 이름을 그대로 씀 · ","")&IF(AND($L17<>"",$L17=$Z17),"개선 후 설명이 똑같음 · ","")&IF(COUNTIFS($C$6:$C$62,$C17,$L$6:$L$62,$L17)>1,"같은 내용이 또 있음 · ","")&IF(AND($U17<>"",$U17=$V17),"필요 자료와 산출물이 같음 · ","")&IF(AND($C17=$C5,$V5<>"",$U17<>"",ISERROR(SEARCH(SUBSTITUTE($V5,CHAR(10)," "),SUBSTITUTE($U17,CHAR(10)," "))),ISERROR(SEARCH(SUBSTITUTE($U17,CHAR(10)," "),SUBSTITUTE($V5,CHAR(10)," ")))),"앞 산출물과 이어지지 않음 · ","")&IF(SUMPRODUCT(--ISNUMBER(SEARCH({"관리한다","처리한다","수행한다","진행한다"},$AW17)))>0,"뭉뚱그린 동사 · ","")&IF(ISNUMBER(SEARCH("하고 ",$AW17)),"한 줄에 동작 2개 · ","")&IF(RIGHT($L17,2)<>"한다","~한다 로 안 끝남 · ","")&IF(AND($P17<>"",N($P17)>60),"1건 60분 넘음 — 더 쪼개세요 · ","")&IF(AND($AA17="AI",$AD17<>"",N($AD17)>0),"AI 혼자 하는데 사람 인원 있음 · ","")&IF(AND($AA17="AI+사람",$AD17<>"",N($AD17)=0),"사람이 확인한다는데 인원 0 · ","")&IF(AND($X17="유지",$Y17="AI"),"그대로 두는데 AI 를 쓴다고 함 · ","")&IF(AND($X17="신설",COUNT($P17,$Q17)>0),"새로 생기는 일인데 현재 공수가 있음 · ","")&IF(AND($X17="삭제",COUNT($AC17,$AD17)>0),"없애는 일인데 개선 후 공수가 있음 · ","")&IF(AND($X17<>"신설",N($AH17)>0,N($AI17)>N($AH17)),"개선 후가 지금보다 더 오래 걸림 · ","")) -> 새로 생기는 일인데 현재 공수가 있음 · | BC17: =IFERROR(IF($L17="",0,1/$AP17),0) -> 0.2
B18: 13 | C18: 1.1.3.5.1 | D18: #4 | E18: 시큐리티 | F18: 마케팅 | G18: Market Intelligence | H18: MI 정보분석 및 시사점 도출 | I18: 시사점 도출 | J18: 환경분석 시사점도출 | K18: =IF($L18="","",$C18&"-"&TEXT(COUNTIFS($C$6:$C18,$C18),"00")) -> 1.1.3.5.1-03 | L18: 관점 간 결론 충돌 여부와 확신도를 확인한다 | M18: 관점별 시사점 사이에 상반된 결론이 존재하는지 여부 | N18: 사람 | P18: 5 | Q18: 1 | R18: 주 | S18: 1 | T18: 0 | U18: 관점별 시사점 | V18: 관점 충돌·확신도 확인 결과 | W18: offline(개인PC) | X18: 신설 | Y18: AI | Z18: 관점 충돌과 확신도가 화면에 표시되어 사람이 판단해야 할 지점을 먼저 드러낸다 | AA18: AI | AE18: 관점별 시사점 | AF18: 관점 충돌·확신도 확인 결과 | AG18: AI Agent DB | AH18: =IF(OR($Q18="",$Q18=0,$P18=""),0,ROUND($P18*$Q18*IFERROR(IF($R18="건별/비정기",$T18,VLOOKUP($R18,'04.코드표'!$K$5:$L$8,2,FALSE)*$S18),0)/60,1)) -> 4.3 | AI18: =IF(OR($AD18="",$AD18=0,$AC18=""),0,ROUND($AC18*$AD18*IFERROR(IF($R18="건별/비정기",$T18,VLOOKUP($R18,'04.코드표'!$K$5:$L$8,2,FALSE)*$S18),0)/60,1)) -> 0 | AJ18: =IF($L18="","",$AH18-$AI18) -> 4.3 | AK18: =IF($L18="","",ROUND($AJ18/'04.코드표'!$L$11,2)) -> 0 | AL18: 상 | AM18: 서로 다른 해석이 있어도 드러나지 않아 한 사람의 결론이 그대로 굳어진다 | AP18: =IF($L18="","",COUNTIFS($C$6:$C$62,$C18)) -> 5 | AQ18: =IF($L18="","",IF($AP18=1,"⚠ 1개뿐 — 더 쪼개세요",IF($AP18=2,"△ 2개뿐 — 빠진 단계 확인",IF($AZ18<=2,"△ 하는 일이 "&$AZ18&"가지뿐 — 빠진 단계 확인","○ 좋음 (하는 일 "&$AZ18&"가지)")))) -> ○ 좋음 (하는 일 4가지) | AR18: =IF($L18="","",IF($BA18=0,"○ 다 채웠음","⚠ "&$BA18&"칸 비었음")) -> ⚠ 2칸 비었음 | AS18: =IF($L18="","",IF($BB18="","○ 문제 없음","⚠ "&LEFT($BB18,LEN($BB18)-3))) -> ⚠ 새로 생기는 일인데 현재 공수가 있음 | AV18: =IF($L18="","",TRIM(RIGHT(SUBSTITUTE($AW18," ",REPT(" ",120)),120))) -> 확인한다 | AW18: =SUBSTITUTE($L18,CHAR(10)," ") -> 관점 간 결론 충돌 여부와 확신도를 확인한다 | AX18: =SUBSTITUTE($J18,CHAR(10)," ") -> 환경분석 시사점도출 | AY18: =IF($L18="","",IF(SUMPRODUCT(--ISNUMBER(SEARCH({"조회","수집","추출","검색","파악","취합","조달","접수","연계","연동","선별","확보","입수","조사","식별","검출","감지","스크랩","필터링"},$AV18)))>0,"조회",IF(SUMPRODUCT(--ISNUMBER(SEARCH({"검토","검증","판정","판별","확인","승인","선정","대조","점검","분류","확정","평가","판단","심사","검수","비교","결정","구분","진단","판독","협의"},$AV18)))>0,"검증",IF(SUMPRODUCT(--ISNUMBER(SEARCH({"등록","발송","배포","제출","보고","이관","업로드","비치","공유","통보","알림","축적","저장","안내","제시","전달","회신","게시","기록","전파","제공","공지","요청","지시","배정","회부"},$AV18)))>0,"등록",IF(SUMPRODUCT(--ISNUMBER(SEARCH({"작성","생성","산출","제작","입력","정리","집계","분석","정형화","도출","보정","구성","정렬","반영","수립","설계","보완","요약","번역","정의","산정","갱신","수정","편성","설정","누적","가공","변환","시각화","편집","통합","부여","정제","기입","조정","제거","표시","채번"},$AV18)))>0,"작성","기타"))))) -> 검증 | AZ18: =IF($L18="","",(COUNTIFS($C$6:$C$62,$C18,$AY$6:$AY$62,"조회")>0)+(COUNTIFS($C$6:$C$62,$C18,$AY$6:$AY$62,"작성")>0)+(COUNTIFS($C$6:$C$62,$C18,$AY$6:$AY$62,"검증")>0)+(COUNTIFS($C$6:$C$62,$C18,$AY$6:$AY$62,"등록")>0)) -> 4 | BA18: =IF($L18="",0,IF($X18="신설",0,COUNTBLANK($N18)+COUNTBLANK($P18)+COUNTBLANK($Q18)+COUNTBLANK($R18)+IF($R18="건별/비정기",COUNTBLANK($T18),IF($R18="",0,COUNTBLANK($S18))))+IF($X18="삭제",0,COUNTBLANK($AC18)+COUNTBLANK($AD18))) -> 2 | BB18: =IF($L18="","",IF(AND($AX18<>"",ISNUMBER(SEARCH($AX18,$AW18))),"L5 이름을 그대로 씀 · ","")&IF(AND($L18<>"",$L18=$Z18),"개선 후 설명이 똑같음 · ","")&IF(COUNTIFS($C$6:$C$62,$C18,$L$6:$L$62,$L18)>1,"같은 내용이 또 있음 · ","")&IF(AND($U18<>"",$U18=$V18),"필요 자료와 산출물이 같음 · ","")&IF(AND($C18=$C5,$V5<>"",$U18<>"",ISERROR(SEARCH(SUBSTITUTE($V5,CHAR(10)," "),SUBSTITUTE($U18,CHAR(10)," "))),ISERROR(SEARCH(SUBSTITUTE($U18,CHAR(10)," "),SUBSTITUTE($V5,CHAR(10)," ")))),"앞 산출물과 이어지지 않음 · ","")&IF(SUMPRODUCT(--ISNUMBER(SEARCH({"관리한다","처리한다","수행한다","진행한다"},$AW18)))>0,"뭉뚱그린 동사 · ","")&IF(ISNUMBER(SEARCH("하고 ",$AW18)),"한 줄에 동작 2개 · ","")&IF(RIGHT($L18,2)<>"한다","~한다 로 안 끝남 · ","")&IF(AND($P18<>"",N($P18)>60),"1건 60분 넘음 — 더 쪼개세요 · ","")&IF(AND($AA18="AI",$AD18<>"",N($AD18)>0),"AI 혼자 하는데 사람 인원 있음 · ","")&IF(AND($AA18="AI+사람",$AD18<>"",N($AD18)=0),"사람이 확인한다는데 인원 0 · ","")&IF(AND($X18="유지",$Y18="AI"),"그대로 두는데 AI 를 쓴다고 함 · ","")&IF(AND($X18="신설",COUNT($P18,$Q18)>0),"새로 생기는 일인데 현재 공수가 있음 · ","")&IF(AND($X18="삭제",COUNT($AC18,$AD18)>0),"없애는 일인데 개선 후 공수가 있음 · ","")&IF(AND($X18<>"신설",N($AH18)>0,N($AI18)>N($AH18)),"개선 후가 지금보다 더 오래 걸림 · ","")) -> 새로 생기는 일인데 현재 공수가 있음 · | BC18: =IFERROR(IF($L18="",0,1/$AP18),0) -> 0.2
